package mark123mark.mods.transcraft.WorldGen.TransManaia;

import java.util.Random;

import mark123mark.mods.transcraft.Transcraft;
import mark123mark.mods.transcraft.WorldGen.FishyWorldGenBase;
import net.minecraft.block.Block;
import net.minecraft.item.Item;
import net.minecraft.item.ItemStack;
import net.minecraft.tileentity.TileEntityChest;
import net.minecraft.world.World;
import net.minecraft.world.gen.feature.WorldGenerator;
import cpw.mods.fml.common.FMLLog;

public class OldHouse extends WorldGenerator
{

	public OldHouse()
	{
	}

	@Override
	public boolean generate(World world, Random rand, int i, int j, int k)
	{

		world.setBlock(i + 0, j + 0, k + 0, 0);
		world.setBlock(i + 0, j + 0, k + 1, 0);
		world.setBlock(i + 0, j + 0, k + 2, 0);
		world.setBlock(i + 0, j + 0, k + 3, 0);
		world.setBlock(i + 0, j + 0, k + 4, 0);
		world.setBlock(i + 0, j + 0, k + 5, 0);
		world.setBlock(i + 0, j + 0, k + 6, 0);
		world.setBlock(i + 0, j + 0, k + 7, 0);
		world.setBlock(i + 0, j + 0, k + 8, 0);
		world.setBlock(i + 0, j + 0, k + 9, 0);
		world.setBlock(i + 0, j + 0, k + 10, 0);
		world.setBlock(i + 0, j + 0, k + 11, 0);
		world.setBlock(i + 0, j + 0, k + 12, 0);
		world.setBlock(i + 0, j + 1, k + 0, 0);
		world.setBlock(i + 0, j + 1, k + 1, 0);
		world.setBlock(i + 0, j + 1, k + 2, 0);
		world.setBlock(i + 0, j + 1, k + 3, 0);
		world.setBlock(i + 0, j + 1, k + 4, 0);
		world.setBlock(i + 0, j + 1, k + 5, 0);
		world.setBlock(i + 0, j + 1, k + 6, 0);
		world.setBlock(i + 0, j + 1, k + 7, 0);
		world.setBlock(i + 0, j + 1, k + 8, 0);
		world.setBlock(i + 0, j + 1, k + 9, 0);
		world.setBlock(i + 0, j + 1, k + 10, 0);
		world.setBlock(i + 0, j + 1, k + 11, 0);
		world.setBlock(i + 0, j + 1, k + 12, 0);
		world.setBlock(i + 0, j + 2, k + 0, 0);
		world.setBlock(i + 0, j + 2, k + 1, 0);
		world.setBlock(i + 0, j + 2, k + 2, 0);
		world.setBlock(i + 0, j + 2, k + 3, 0);
		world.setBlock(i + 0, j + 2, k + 4, 0);
		world.setBlock(i + 0, j + 2, k + 5, 0);
		world.setBlock(i + 0, j + 2, k + 6, 0);
		world.setBlock(i + 0, j + 2, k + 7, 0);
		world.setBlock(i + 0, j + 2, k + 8, 0);
		world.setBlock(i + 0, j + 2, k + 9, 0);
		world.setBlock(i + 0, j + 2, k + 10, 0);
		world.setBlock(i + 0, j + 2, k + 11, 0);
		world.setBlock(i + 0, j + 2, k + 12, 0);
		world.setBlock(i + 0, j + 3, k + 0, 0);
		world.setBlock(i + 0, j + 3, k + 1, 0);
		world.setBlock(i + 0, j + 3, k + 2, 0);
		world.setBlock(i + 0, j + 3, k + 3, 0);
		world.setBlock(i + 0, j + 3, k + 4, 0);
		world.setBlock(i + 0, j + 3, k + 5, 0);
		world.setBlock(i + 0, j + 3, k + 6, 0);
		world.setBlock(i + 0, j + 3, k + 7, 0);
		world.setBlock(i + 0, j + 3, k + 8, 0);
		world.setBlock(i + 0, j + 3, k + 9, 0);
		world.setBlock(i + 0, j + 3, k + 10, 0);
		world.setBlock(i + 0, j + 3, k + 11, 0);
		world.setBlock(i + 0, j + 3, k + 12, 0);
		world.setBlock(i + 0, j + 4, k + 0, 0);
		world.setBlock(i + 0, j + 4, k + 1, 0);
		world.setBlock(i + 0, j + 4, k + 2, 0);
		world.setBlock(i + 0, j + 4, k + 3, 0);
		world.setBlock(i + 0, j + 4, k + 4, 0);
		world.setBlock(i + 0, j + 4, k + 5, 0);
		world.setBlock(i + 0, j + 4, k + 6, 0);
		world.setBlock(i + 0, j + 4, k + 7, 0);
		world.setBlock(i + 0, j + 4, k + 8, 0);
		world.setBlock(i + 0, j + 4, k + 9, 0);
		world.setBlock(i + 0, j + 4, k + 10, 0);
		world.setBlock(i + 0, j + 4, k + 11, 0);
		world.setBlock(i + 0, j + 4, k + 12, 0);
		world.setBlock(i + 0, j + 5, k + 0, 0);
		world.setBlock(i + 0, j + 5, k + 1, 0);
		world.setBlock(i + 0, j + 5, k + 2, 0);
		world.setBlock(i + 0, j + 5, k + 3, 0);
		world.setBlock(i + 0, j + 5, k + 4, 0);
		world.setBlock(i + 0, j + 5, k + 5, 0);
		world.setBlock(i + 0, j + 5, k + 6, 0);
		world.setBlock(i + 0, j + 5, k + 7, 0);
		world.setBlock(i + 0, j + 5, k + 8, 0);
		world.setBlock(i + 0, j + 5, k + 9, 0);
		world.setBlock(i + 0, j + 5, k + 10, 0);
		world.setBlock(i + 0, j + 5, k + 11, 0);
		world.setBlock(i + 0, j + 5, k + 12, 0);
		world.setBlock(i + 0, j + 6, k + 0, 0);
		world.setBlock(i + 0, j + 6, k + 1, 0);
		world.setBlock(i + 0, j + 6, k + 2, 0);
		world.setBlock(i + 0, j + 6, k + 3, 0);
		world.setBlock(i + 0, j + 6, k + 4, 0);
		world.setBlock(i + 0, j + 6, k + 5, 0);
		world.setBlock(i + 0, j + 6, k + 6, 0);
		world.setBlock(i + 0, j + 6, k + 7, 0);
		world.setBlock(i + 0, j + 6, k + 8, 0);
		world.setBlock(i + 0, j + 6, k + 9, 0);
		world.setBlock(i + 0, j + 6, k + 10, 0);
		world.setBlock(i + 0, j + 6, k + 11, 0);
		world.setBlock(i + 0, j + 6, k + 12, 0);
		world.setBlock(i + 0, j + 7, k + 0, 0);
		world.setBlock(i + 0, j + 7, k + 1, 0);
		world.setBlock(i + 0, j + 7, k + 2, 0);
		world.setBlock(i + 0, j + 7, k + 3, 0);
		world.setBlock(i + 0, j + 7, k + 4, 0);
		world.setBlock(i + 0, j + 7, k + 5, 0);
		world.setBlock(i + 0, j + 7, k + 6, 0);
		world.setBlock(i + 0, j + 7, k + 7, 0);
		world.setBlock(i + 0, j + 7, k + 8, 0);
		world.setBlock(i + 0, j + 7, k + 9, 0);
		world.setBlock(i + 0, j + 7, k + 10, 0);
		world.setBlock(i + 0, j + 7, k + 11, 0);
		world.setBlock(i + 0, j + 7, k + 12, 0);
		world.setBlock(i + 0, j + 8, k + 0, 0);
		world.setBlock(i + 0, j + 8, k + 1, 0);
		world.setBlock(i + 0, j + 8, k + 2, 0);
		world.setBlock(i + 0, j + 8, k + 3, 0);
		world.setBlock(i + 0, j + 8, k + 4, 0);
		world.setBlock(i + 0, j + 8, k + 5, 0);
		world.setBlock(i + 0, j + 8, k + 6, 0);
		world.setBlock(i + 0, j + 8, k + 7, 0);
		world.setBlock(i + 0, j + 8, k + 8, 0);
		world.setBlock(i + 0, j + 8, k + 9, 0);
		world.setBlock(i + 0, j + 8, k + 10, 0);
		world.setBlock(i + 0, j + 8, k + 11, 0);
		world.setBlock(i + 0, j + 8, k + 12, 0);
		world.setBlock(i + 0, j + 9, k + 0, 0);
		world.setBlock(i + 0, j + 9, k + 1, 0);
		world.setBlock(i + 0, j + 9, k + 2, 0);
		world.setBlock(i + 0, j + 9, k + 3, 0);
		world.setBlock(i + 0, j + 9, k + 4, 0);
		world.setBlock(i + 0, j + 9, k + 5, 0);
		world.setBlock(i + 0, j + 9, k + 6, 0);
		world.setBlock(i + 0, j + 9, k + 7, 0);
		world.setBlock(i + 0, j + 9, k + 8, 0);
		world.setBlock(i + 0, j + 9, k + 9, 0);
		world.setBlock(i + 0, j + 9, k + 10, 0);
		world.setBlock(i + 0, j + 9, k + 11, 0);
		world.setBlock(i + 0, j + 9, k + 12, 0);
		world.setBlock(i + 0, j + 10, k + 0, 0);
		world.setBlock(i + 0, j + 10, k + 1, 0);
		world.setBlock(i + 0, j + 10, k + 2, 0);
		world.setBlock(i + 0, j + 10, k + 3, 0);
		world.setBlock(i + 0, j + 10, k + 4, 0);
		world.setBlock(i + 0, j + 10, k + 5, 0);
		world.setBlock(i + 0, j + 10, k + 6, 0);
		world.setBlock(i + 0, j + 10, k + 8, 0);
		world.setBlock(i + 0, j + 10, k + 9, 0);
		world.setBlock(i + 0, j + 10, k + 10, 0);
		world.setBlock(i + 0, j + 10, k + 11, 0);
		world.setBlock(i + 0, j + 10, k + 12, 0);
		world.setBlock(i + 0, j + 11, k + 0, 0);
		world.setBlock(i + 0, j + 11, k + 1, 0);
		world.setBlock(i + 0, j + 11, k + 2, 0);
		world.setBlock(i + 0, j + 11, k + 3, 0);
		world.setBlock(i + 0, j + 11, k + 4, 0);
		world.setBlock(i + 0, j + 11, k + 5, 0);
		world.setBlock(i + 0, j + 11, k + 6, 0);
		world.setBlock(i + 0, j + 11, k + 8, 0);
		world.setBlock(i + 0, j + 11, k + 9, 0);
		world.setBlock(i + 0, j + 11, k + 10, 0);
		world.setBlock(i + 0, j + 11, k + 11, 0);
		world.setBlock(i + 0, j + 11, k + 12, 0);
		world.setBlock(i + 0, j + 12, k + 0, 0);
		world.setBlock(i + 0, j + 12, k + 1, 0);
		world.setBlock(i + 0, j + 12, k + 2, 0);
		world.setBlock(i + 0, j + 12, k + 3, 0);
		world.setBlock(i + 0, j + 12, k + 4, 0);
		world.setBlock(i + 0, j + 12, k + 5, Block.web.blockID);
		world.setBlock(i + 0, j + 12, k + 6, 0);
		world.setBlock(i + 0, j + 12, k + 7, 0);
		world.setBlock(i + 0, j + 12, k + 8, Block.web.blockID);
		world.setBlock(i + 0, j + 12, k + 9, 0);
		world.setBlock(i + 0, j + 12, k + 10, 0);
		world.setBlock(i + 0, j + 12, k + 11, 0);
		world.setBlock(i + 0, j + 12, k + 12, 0);
		world.setBlock(i + 0, j + 13, k + 0, 0);
		world.setBlock(i + 0, j + 13, k + 1, 0);
		world.setBlock(i + 0, j + 13, k + 2, 0);
		world.setBlock(i + 0, j + 13, k + 3, 0);
		world.setBlock(i + 0, j + 13, k + 4, Block.web.blockID);
		world.setBlock(i + 0, j + 13, k + 5, 0);
		world.setBlock(i + 0, j + 13, k + 6, 0);
		world.setBlock(i + 0, j + 13, k + 7, 0);
		world.setBlock(i + 0, j + 13, k + 8, 0);
		world.setBlock(i + 0, j + 13, k + 9, 0);
		world.setBlock(i + 0, j + 13, k + 10, 0);
		world.setBlock(i + 0, j + 13, k + 11, 0);
		world.setBlock(i + 0, j + 13, k + 12, 0);
		world.setBlock(i + 0, j + 14, k + 0, 0);
		world.setBlock(i + 0, j + 14, k + 1, 0);
		world.setBlock(i + 0, j + 14, k + 2, 0);
		world.setBlock(i + 0, j + 14, k + 3, 0);
		world.setBlock(i + 0, j + 14, k + 4, 0);
		world.setBlock(i + 0, j + 14, k + 6, Block.web.blockID);
		world.setBlock(i + 0, j + 14, k + 7, 0);
		world.setBlock(i + 0, j + 14, k + 8, 0);
		world.setBlock(i + 0, j + 14, k + 9, 0);
		world.setBlock(i + 0, j + 14, k + 10, 0);
		world.setBlock(i + 0, j + 14, k + 11, 0);
		world.setBlock(i + 0, j + 14, k + 12, 0);
		world.setBlock(i + 0, j + 15, k + 0, 0);
		world.setBlock(i + 0, j + 15, k + 1, 0);
		world.setBlock(i + 0, j + 15, k + 2, 0);
		world.setBlock(i + 0, j + 15, k + 3, 0);
		world.setBlock(i + 0, j + 15, k + 4, 0);
		world.setBlock(i + 0, j + 15, k + 5, 0);
		world.setBlock(i + 0, j + 15, k + 6, 0);
		world.setBlock(i + 0, j + 15, k + 8, 0);
		world.setBlock(i + 0, j + 15, k + 9, 0);
		world.setBlock(i + 0, j + 15, k + 10, 0);
		world.setBlock(i + 0, j + 15, k + 11, 0);
		world.setBlock(i + 0, j + 15, k + 12, 0);
		world.setBlock(i + 0, j + 16, k + 0, 0);
		world.setBlock(i + 0, j + 16, k + 1, 0);
		world.setBlock(i + 0, j + 16, k + 2, 0);
		world.setBlock(i + 0, j + 16, k + 3, 0);
		world.setBlock(i + 0, j + 16, k + 4, 0);
		world.setBlock(i + 0, j + 16, k + 5, 0);
		world.setBlock(i + 0, j + 16, k + 6, 0);
		world.setBlock(i + 0, j + 16, k + 7, 0);
		world.setBlock(i + 0, j + 16, k + 8, 0);
		world.setBlock(i + 0, j + 16, k + 9, 0);
		world.setBlock(i + 0, j + 16, k + 10, 0);
		world.setBlock(i + 0, j + 16, k + 11, 0);
		world.setBlock(i + 0, j + 16, k + 12, 0);
		world.setBlock(i + 0, j + 17, k + 0, 0);
		world.setBlock(i + 0, j + 17, k + 1, 0);
		world.setBlock(i + 0, j + 17, k + 2, 0);
		world.setBlock(i + 0, j + 17, k + 3, 0);
		world.setBlock(i + 0, j + 17, k + 4, 0);
		world.setBlock(i + 0, j + 17, k + 5, 0);
		world.setBlock(i + 0, j + 17, k + 6, 0);
		world.setBlock(i + 0, j + 17, k + 7, 0);
		world.setBlock(i + 0, j + 17, k + 8, 0);
		world.setBlock(i + 0, j + 17, k + 9, 0);
		world.setBlock(i + 0, j + 17, k + 10, 0);
		world.setBlock(i + 0, j + 17, k + 11, 0);
		world.setBlock(i + 0, j + 17, k + 12, 0);
		world.setBlock(i + 0, j + 18, k + 0, 0);
		world.setBlock(i + 0, j + 18, k + 1, 0);
		world.setBlock(i + 0, j + 18, k + 2, 0);
		world.setBlock(i + 0, j + 18, k + 3, 0);
		world.setBlock(i + 0, j + 18, k + 4, 0);
		world.setBlock(i + 0, j + 18, k + 5, 0);
		world.setBlock(i + 0, j + 18, k + 6, 0);
		world.setBlock(i + 0, j + 18, k + 7, 0);
		world.setBlock(i + 0, j + 18, k + 8, 0);
		world.setBlock(i + 0, j + 18, k + 9, 0);
		world.setBlock(i + 0, j + 18, k + 10, 0);
		world.setBlock(i + 0, j + 18, k + 11, 0);
		world.setBlock(i + 0, j + 18, k + 12, 0);
		world.setBlock(i + 0, j + 19, k + 0, 0);
		world.setBlock(i + 0, j + 19, k + 1, 0);
		world.setBlock(i + 0, j + 19, k + 2, 0);
		world.setBlock(i + 0, j + 19, k + 3, 0);
		world.setBlock(i + 0, j + 19, k + 4, 0);
		world.setBlock(i + 0, j + 19, k + 5, 0);
		world.setBlock(i + 0, j + 19, k + 6, 0);
		world.setBlock(i + 0, j + 19, k + 7, 0);
		world.setBlock(i + 0, j + 19, k + 8, 0);
		world.setBlock(i + 0, j + 19, k + 9, 0);
		world.setBlock(i + 0, j + 19, k + 10, 0);
		world.setBlock(i + 0, j + 19, k + 11, 0);
		world.setBlock(i + 0, j + 19, k + 12, 0);
		world.setBlock(i + 1, j + 0, k + 0, 0);
		world.setBlock(i + 1, j + 0, k + 1, 0);
		world.setBlock(i + 1, j + 0, k + 2, 0);
		world.setBlock(i + 1, j + 0, k + 3, 0);
		world.setBlock(i + 1, j + 0, k + 4, 0);
		world.setBlock(i + 1, j + 0, k + 5, 0);
		world.setBlock(i + 1, j + 0, k + 6, 0);
		world.setBlock(i + 1, j + 0, k + 7, 0);
		world.setBlock(i + 1, j + 0, k + 8, 0);
		world.setBlock(i + 1, j + 0, k + 9, 0);
		world.setBlock(i + 1, j + 0, k + 10, 0);
		world.setBlock(i + 1, j + 0, k + 11, 0);
		world.setBlock(i + 1, j + 0, k + 12, 0);
		world.setBlock(i + 1, j + 1, k + 0, 0);
		world.setBlock(i + 1, j + 1, k + 1, 0);
		world.setBlock(i + 1, j + 1, k + 2, 0);
		world.setBlock(i + 1, j + 1, k + 3, 0);
		world.setBlock(i + 1, j + 1, k + 4, 0);
		world.setBlock(i + 1, j + 1, k + 5, 0);
		world.setBlock(i + 1, j + 1, k + 6, 0);
		world.setBlock(i + 1, j + 1, k + 7, 0);
		world.setBlock(i + 1, j + 1, k + 8, 0);
		world.setBlock(i + 1, j + 1, k + 9, 0);
		world.setBlock(i + 1, j + 1, k + 10, 0);
		world.setBlock(i + 1, j + 1, k + 11, 0);
		world.setBlock(i + 1, j + 1, k + 12, 0);
		world.setBlock(i + 1, j + 2, k + 0, 0);
		world.setBlock(i + 1, j + 2, k + 1, 0);
		world.setBlock(i + 1, j + 2, k + 2, 0);
		world.setBlock(i + 1, j + 2, k + 3, 0);
		world.setBlock(i + 1, j + 2, k + 4, 0);
		world.setBlock(i + 1, j + 2, k + 5, 0);
		world.setBlock(i + 1, j + 2, k + 6, 0);
		world.setBlock(i + 1, j + 2, k + 7, 0);
		world.setBlock(i + 1, j + 2, k + 8, 0);
		world.setBlock(i + 1, j + 2, k + 9, 0);
		world.setBlock(i + 1, j + 2, k + 10, 0);
		world.setBlock(i + 1, j + 2, k + 11, 0);
		world.setBlock(i + 1, j + 2, k + 12, 0);
		world.setBlock(i + 1, j + 3, k + 0, 0);
		world.setBlock(i + 1, j + 3, k + 1, 0);
		world.setBlock(i + 1, j + 3, k + 2, 0);
		world.setBlock(i + 1, j + 3, k + 3, 0);
		world.setBlock(i + 1, j + 3, k + 4, 0);
		world.setBlock(i + 1, j + 3, k + 5, 0);
		world.setBlock(i + 1, j + 3, k + 6, 0);
		world.setBlock(i + 1, j + 3, k + 7, 0);
		world.setBlock(i + 1, j + 3, k + 8, 0);
		world.setBlock(i + 1, j + 3, k + 9, 0);
		world.setBlock(i + 1, j + 3, k + 10, 0);
		world.setBlock(i + 1, j + 3, k + 11, 0);
		world.setBlock(i + 1, j + 3, k + 12, 0);
		world.setBlock(i + 1, j + 4, k + 0, 0);
		world.setBlock(i + 1, j + 4, k + 1, 0);
		world.setBlock(i + 1, j + 4, k + 2, 0);
		world.setBlock(i + 1, j + 4, k + 3, 0);
		world.setBlock(i + 1, j + 4, k + 4, 0);
		world.setBlock(i + 1, j + 4, k + 5, 0);
		world.setBlock(i + 1, j + 4, k + 6, 0);
		world.setBlock(i + 1, j + 4, k + 7, 0);
		world.setBlock(i + 1, j + 4, k + 8, 0);
		world.setBlock(i + 1, j + 4, k + 9, 0);
		world.setBlock(i + 1, j + 4, k + 10, 0);
		world.setBlock(i + 1, j + 4, k + 11, 0);
		world.setBlock(i + 1, j + 4, k + 12, 0);
		world.setBlock(i + 1, j + 5, k + 0, 0);
		world.setBlock(i + 1, j + 5, k + 1, 0);
		world.setBlock(i + 1, j + 5, k + 2, 0);
		world.setBlock(i + 1, j + 5, k + 3, 0);
		world.setBlock(i + 1, j + 5, k + 4, 0);
		world.setBlock(i + 1, j + 5, k + 5, 0);
		world.setBlock(i + 1, j + 5, k + 6, 0);
		world.setBlock(i + 1, j + 5, k + 7, 0);
		world.setBlock(i + 1, j + 5, k + 8, 0);
		world.setBlock(i + 1, j + 5, k + 9, 0);
		world.setBlock(i + 1, j + 5, k + 10, 0);
		world.setBlock(i + 1, j + 5, k + 11, 0);
		world.setBlock(i + 1, j + 5, k + 12, 0);
		world.setBlock(i + 1, j + 6, k + 0, 0);
		world.setBlock(i + 1, j + 6, k + 1, 0);
		world.setBlock(i + 1, j + 6, k + 2, 0);
		world.setBlock(i + 1, j + 6, k + 3, 0);
		world.setBlock(i + 1, j + 6, k + 4, 0);
		world.setBlock(i + 1, j + 6, k + 5, 0);
		world.setBlock(i + 1, j + 6, k + 6, 0);
		world.setBlock(i + 1, j + 6, k + 7, 0);
		world.setBlock(i + 1, j + 6, k + 8, 0);
		world.setBlock(i + 1, j + 6, k + 9, 0);
		world.setBlock(i + 1, j + 6, k + 10, 0);
		world.setBlock(i + 1, j + 6, k + 11, 0);
		world.setBlock(i + 1, j + 6, k + 12, 0);
		world.setBlock(i + 1, j + 7, k + 0, 0);
		world.setBlock(i + 1, j + 7, k + 1, 0);
		world.setBlock(i + 1, j + 7, k + 2, 0);
		world.setBlock(i + 1, j + 7, k + 3, 0);
		world.setBlock(i + 1, j + 7, k + 4, 0);
		world.setBlock(i + 1, j + 7, k + 5, 0);
		world.setBlock(i + 1, j + 7, k + 6, 0);
		world.setBlock(i + 1, j + 7, k + 7, 0);
		world.setBlock(i + 1, j + 7, k + 8, 0);
		world.setBlock(i + 1, j + 7, k + 9, 0);
		world.setBlock(i + 1, j + 7, k + 10, 0);
		world.setBlock(i + 1, j + 7, k + 11, 0);
		world.setBlock(i + 1, j + 7, k + 12, 0);
		world.setBlock(i + 1, j + 8, k + 0, 0);
		world.setBlock(i + 1, j + 8, k + 1, 0);
		world.setBlock(i + 1, j + 8, k + 2, 0);
		world.setBlock(i + 1, j + 8, k + 3, 0);
		world.setBlock(i + 1, j + 8, k + 4, 0);
		world.setBlock(i + 1, j + 8, k + 5, 0);
		world.setBlock(i + 1, j + 8, k + 7, 0);
		world.setBlock(i + 1, j + 8, k + 8, 0);
		world.setBlock(i + 1, j + 8, k + 9, 0);
		world.setBlock(i + 1, j + 8, k + 10, 0);
		world.setBlock(i + 1, j + 8, k + 11, 0);
		world.setBlock(i + 1, j + 8, k + 12, 0);
		world.setBlock(i + 1, j + 9, k + 0, 0);
		world.setBlock(i + 1, j + 9, k + 1, 0);
		world.setBlock(i + 1, j + 9, k + 2, 0);
		world.setBlock(i + 1, j + 9, k + 3, 0);
		world.setBlock(i + 1, j + 9, k + 4, 0);
		world.setBlock(i + 1, j + 9, k + 5, 0);
		world.setBlock(i + 1, j + 9, k + 7, 0);
		world.setBlock(i + 1, j + 9, k + 8, 0);
		world.setBlock(i + 1, j + 9, k + 9, 0);
		world.setBlock(i + 1, j + 9, k + 10, 0);
		world.setBlock(i + 1, j + 9, k + 11, 0);
		world.setBlock(i + 1, j + 9, k + 12, 0);
		world.setBlock(i + 1, j + 10, k + 0, 0);
		world.setBlock(i + 1, j + 10, k + 1, 0);
		world.setBlock(i + 1, j + 10, k + 2, 0);
		world.setBlock(i + 1, j + 10, k + 3, 0);
		world.setBlock(i + 1, j + 10, k + 4, 0);
		world.setBlock(i + 1, j + 10, k + 6, Block.stoneBrick.blockID);
		world.setBlock(i + 1, j + 10, k + 7, 0);
		world.setBlock(i + 1, j + 10, k + 8, 0);
		world.setBlock(i + 1, j + 10, k + 9, 0);
		world.setBlock(i + 1, j + 10, k + 10, 0);
		world.setBlock(i + 1, j + 10, k + 11, 0);
		world.setBlock(i + 1, j + 10, k + 12, 0);
		world.setBlock(i + 1, j + 11, k + 0, 0);
		world.setBlock(i + 1, j + 11, k + 1, 0);
		world.setBlock(i + 1, j + 11, k + 2, 0);
		world.setBlock(i + 1, j + 11, k + 3, 0);
		world.setBlock(i + 1, j + 11, k + 4, Block.stoneBrick.blockID);
		world.setBlock(i + 1, j + 11, k + 5, Block.stoneBrick.blockID);
		world.setBlock(i + 1, j + 11, k + 6, Block.stoneBrick.blockID);
		world.setBlock(i + 1, j + 11, k + 7, Block.stoneBrick.blockID);
		world.setBlock(i + 1, j + 11, k + 8, Block.stoneBrick.blockID);
		world.setBlock(i + 1, j + 11, k + 9, Block.web.blockID);
		world.setBlock(i + 1, j + 11, k + 10, 0);
		world.setBlock(i + 1, j + 11, k + 11, 0);
		world.setBlock(i + 1, j + 11, k + 12, 0);
		world.setBlock(i + 1, j + 12, k + 0, 0);
		world.setBlock(i + 1, j + 12, k + 1, 0);
		world.setBlock(i + 1, j + 12, k + 2, 0);
		world.setBlock(i + 1, j + 12, k + 4, Block.stoneBrick.blockID);
		world.setBlock(i + 1, j + 12, k + 5, Block.glass.blockID);
		world.setBlock(i + 1, j + 12, k + 6, Block.web.blockID);
		world.setBlock(i + 1, j + 12, k + 7, Block.glass.blockID);
		world.setBlock(i + 1, j + 12, k + 8, Block.stoneBrick.blockID);
		world.setBlock(i + 1, j + 12, k + 9, 0);
		world.setBlock(i + 1, j + 12, k + 10, 0);
		world.setBlock(i + 1, j + 12, k + 11, 0);
		world.setBlock(i + 1, j + 12, k + 12, 0);
		world.setBlock(i + 1, j + 13, k + 0, 0);
		world.setBlock(i + 1, j + 13, k + 1, 0);
		world.setBlock(i + 1, j + 13, k + 2, 0);
		world.setBlock(i + 1, j + 13, k + 4, Block.stoneBrick.blockID);
		world.setBlock(i + 1, j + 13, k + 5, Block.glass.blockID);
		world.setBlock(i + 1, j + 13, k + 6, Block.glass.blockID);
		world.setBlock(i + 1, j + 13, k + 7, Block.glass.blockID);
		world.setBlock(i + 1, j + 13, k + 8, Block.stoneBrick.blockID);
		world.setBlock(i + 1, j + 13, k + 9, 0);
		world.setBlock(i + 1, j + 13, k + 10, 0);
		world.setBlock(i + 1, j + 13, k + 11, 0);
		world.setBlock(i + 1, j + 13, k + 12, 0);
		world.setBlock(i + 1, j + 14, k + 0, 0);
		world.setBlock(i + 1, j + 14, k + 1, 0);
		world.setBlock(i + 1, j + 14, k + 2, 0);
		world.setBlock(i + 1, j + 14, k + 3, 0);
		world.setBlock(i + 1, j + 14, k + 4, Block.stoneBrick.blockID);
		world.setBlock(i + 1, j + 14, k + 5, Block.stoneBrick.blockID);
		world.setBlock(i + 1, j + 14, k + 6, Block.stoneBrick.blockID);
		world.setBlock(i + 1, j + 14, k + 7, Block.stoneBrick.blockID);
		world.setBlock(i + 1, j + 14, k + 8, Block.stoneBrick.blockID);
		world.setBlock(i + 1, j + 14, k + 9, 0);
		world.setBlock(i + 1, j + 14, k + 10, 0);
		world.setBlock(i + 1, j + 14, k + 11, 0);
		world.setBlock(i + 1, j + 14, k + 12, 0);
		world.setBlock(i + 1, j + 15, k + 0, 0);
		world.setBlock(i + 1, j + 15, k + 1, 0);
		world.setBlock(i + 1, j + 15, k + 2, 0);
		world.setBlock(i + 1, j + 15, k + 3, 0);
		world.setBlock(i + 1, j + 15, k + 4, 0);
		world.setBlock(i + 1, j + 15, k + 5, Block.stoneBrick.blockID);
		world.setBlock(i + 1, j + 15, k + 6, Block.stoneBrick.blockID);
		world.setBlock(i + 1, j + 15, k + 7, Block.stoneBrick.blockID);
		world.setBlock(i + 1, j + 15, k + 8, 0);
		world.setBlock(i + 1, j + 15, k + 9, 0);
		world.setBlock(i + 1, j + 15, k + 10, 0);
		world.setBlock(i + 1, j + 15, k + 11, 0);
		world.setBlock(i + 1, j + 15, k + 12, 0);
		world.setBlock(i + 1, j + 16, k + 0, 0);
		world.setBlock(i + 1, j + 16, k + 1, 0);
		world.setBlock(i + 1, j + 16, k + 2, 0);
		world.setBlock(i + 1, j + 16, k + 3, 0);
		world.setBlock(i + 1, j + 16, k + 4, 0);
		world.setBlock(i + 1, j + 16, k + 5, 0);
		world.setBlock(i + 1, j + 16, k + 6, Block.stoneBrick.blockID);
		world.setBlock(i + 1, j + 16, k + 7, Block.web.blockID);
		world.setBlock(i + 1, j + 16, k + 8, 0);
		world.setBlock(i + 1, j + 16, k + 9, 0);
		world.setBlock(i + 1, j + 16, k + 10, 0);
		world.setBlock(i + 1, j + 16, k + 11, 0);
		world.setBlock(i + 1, j + 16, k + 12, 0);
		world.setBlock(i + 1, j + 17, k + 0, 0);
		world.setBlock(i + 1, j + 17, k + 1, 0);
		world.setBlock(i + 1, j + 17, k + 2, 0);
		world.setBlock(i + 1, j + 17, k + 3, 0);
		world.setBlock(i + 1, j + 17, k + 4, 0);
		world.setBlock(i + 1, j + 17, k + 5, 0);
		world.setBlock(i + 1, j + 17, k + 6, 0);
		world.setBlock(i + 1, j + 17, k + 7, 0);
		world.setBlock(i + 1, j + 17, k + 8, 0);
		world.setBlock(i + 1, j + 17, k + 9, 0);
		world.setBlock(i + 1, j + 17, k + 10, 0);
		world.setBlock(i + 1, j + 17, k + 11, 0);
		world.setBlock(i + 1, j + 17, k + 12, 0);
		world.setBlock(i + 1, j + 18, k + 0, 0);
		world.setBlock(i + 1, j + 18, k + 1, 0);
		world.setBlock(i + 1, j + 18, k + 2, 0);
		world.setBlock(i + 1, j + 18, k + 3, 0);
		world.setBlock(i + 1, j + 18, k + 4, 0);
		world.setBlock(i + 1, j + 18, k + 5, 0);
		world.setBlock(i + 1, j + 18, k + 6, 0);
		world.setBlock(i + 1, j + 18, k + 7, 0);
		world.setBlock(i + 1, j + 18, k + 8, 0);
		world.setBlock(i + 1, j + 18, k + 9, 0);
		world.setBlock(i + 1, j + 18, k + 10, 0);
		world.setBlock(i + 1, j + 18, k + 11, 0);
		world.setBlock(i + 1, j + 18, k + 12, 0);
		world.setBlock(i + 1, j + 19, k + 0, 0);
		world.setBlock(i + 1, j + 19, k + 1, 0);
		world.setBlock(i + 1, j + 19, k + 2, 0);
		world.setBlock(i + 1, j + 19, k + 3, 0);
		world.setBlock(i + 1, j + 19, k + 4, 0);
		world.setBlock(i + 1, j + 19, k + 5, 0);
		world.setBlock(i + 1, j + 19, k + 6, 0);
		world.setBlock(i + 1, j + 19, k + 7, 0);
		world.setBlock(i + 1, j + 19, k + 8, 0);
		world.setBlock(i + 1, j + 19, k + 9, 0);
		world.setBlock(i + 1, j + 19, k + 10, 0);
		world.setBlock(i + 1, j + 19, k + 11, 0);
		world.setBlock(i + 1, j + 19, k + 12, 0);
		world.setBlock(i + 2, j + 0, k + 0, 0);
		world.setBlock(i + 2, j + 0, k + 1, 0);
		world.setBlock(i + 2, j + 0, k + 2, 0);
		world.setBlock(i + 2, j + 0, k + 3, 0);
		world.setBlock(i + 2, j + 0, k + 4, 0);
		world.setBlock(i + 2, j + 0, k + 5, 0);
		world.setBlock(i + 2, j + 0, k + 6, 0);
		world.setBlock(i + 2, j + 0, k + 7, 0);
		world.setBlock(i + 2, j + 0, k + 8, 0);
		world.setBlock(i + 2, j + 0, k + 9, 0);
		world.setBlock(i + 2, j + 0, k + 11, 0);
		world.setBlock(i + 2, j + 0, k + 12, 0);
		world.setBlock(i + 2, j + 1, k + 0, 0);
		world.setBlock(i + 2, j + 1, k + 1, 0);
		world.setBlock(i + 2, j + 1, k + 2, 0);
		world.setBlock(i + 2, j + 1, k + 3, 0);
		world.setBlock(i + 2, j + 1, k + 4, 0);
		world.setBlock(i + 2, j + 1, k + 5, 0);
		world.setBlock(i + 2, j + 1, k + 6, 0);
		world.setBlock(i + 2, j + 1, k + 7, 0);
		world.setBlock(i + 2, j + 1, k + 8, 0);
		world.setBlock(i + 2, j + 1, k + 9, 0);
		world.setBlock(i + 2, j + 1, k + 11, 0);
		world.setBlock(i + 2, j + 1, k + 12, 0);
		world.setBlock(i + 2, j + 2, k + 0, 0);
		world.setBlock(i + 2, j + 2, k + 1, 0);
		world.setBlock(i + 2, j + 2, k + 4, 0);
		world.setBlock(i + 2, j + 2, k + 5, 0);
		world.setBlock(i + 2, j + 2, k + 6, 0);
		world.setBlock(i + 2, j + 2, k + 7, 0);
		world.setBlock(i + 2, j + 2, k + 8, 0);
		world.setBlock(i + 2, j + 2, k + 9, 0);
		world.setBlock(i + 2, j + 2, k + 11, 0);
		world.setBlock(i + 2, j + 2, k + 12, 0);
		world.setBlock(i + 2, j + 3, k + 0, 0);
		world.setBlock(i + 2, j + 3, k + 1, 0);
		world.setBlock(i + 2, j + 3, k + 3, 0);
		world.setBlock(i + 2, j + 3, k + 4, 0);
		world.setBlock(i + 2, j + 3, k + 5, 0);
		world.setBlock(i + 2, j + 3, k + 6, 0);
		world.setBlock(i + 2, j + 3, k + 7, 0);
		world.setBlock(i + 2, j + 3, k + 8, 0);
		world.setBlock(i + 2, j + 3, k + 9, 0);
		world.setBlock(i + 2, j + 3, k + 11, 0);
		world.setBlock(i + 2, j + 3, k + 12, 0);
		world.setBlock(i + 2, j + 4, k + 0, 0);
		world.setBlock(i + 2, j + 4, k + 1, 0);
		world.setBlock(i + 2, j + 4, k + 3, 0);
		world.setBlock(i + 2, j + 4, k + 5, 0);
		world.setBlock(i + 2, j + 4, k + 6, 0);
		world.setBlock(i + 2, j + 4, k + 8, 0);
		world.setBlock(i + 2, j + 4, k + 9, 0);
		world.setBlock(i + 2, j + 4, k + 12, 0);
		world.setBlock(i + 2, j + 5, k + 0, 0);
		world.setBlock(i + 2, j + 5, k + 1, 0);
		world.setBlock(i + 2, j + 5, k + 3, 0);
		world.setBlock(i + 2, j + 5, k + 5, 0);
		world.setBlock(i + 2, j + 5, k + 6, 0);
		world.setBlock(i + 2, j + 5, k + 8, 0);
		world.setBlock(i + 2, j + 5, k + 9, 0);
		world.setBlock(i + 2, j + 5, k + 11, 0);
		world.setBlock(i + 2, j + 5, k + 12, 0);
		world.setBlock(i + 2, j + 6, k + 0, 0);
		world.setBlock(i + 2, j + 6, k + 1, 0);
		world.setBlock(i + 2, j + 6, k + 3, 0);
		world.setBlock(i + 2, j + 6, k + 5, 0);
		world.setBlock(i + 2, j + 6, k + 6, 0);
		world.setBlock(i + 2, j + 6, k + 7, 0);
		world.setBlock(i + 2, j + 6, k + 8, 0);
		world.setBlock(i + 2, j + 6, k + 9, 0);
		world.setBlock(i + 2, j + 6, k + 10, 0);
		world.setBlock(i + 2, j + 6, k + 11, 0);
		world.setBlock(i + 2, j + 6, k + 12, 0);
		world.setBlock(i + 2, j + 7, k + 0, 0);
		world.setBlock(i + 2, j + 7, k + 1, 0);
		world.setBlock(i + 2, j + 7, k + 5, 0);
		world.setBlock(i + 2, j + 7, k + 6, 0);
		world.setBlock(i + 2, j + 7, k + 7, 0);
		world.setBlock(i + 2, j + 7, k + 9, 0);
		world.setBlock(i + 2, j + 7, k + 10, 0);
		world.setBlock(i + 2, j + 7, k + 12, 0);
		world.setBlock(i + 2, j + 8, k + 0, 0);
		world.setBlock(i + 2, j + 8, k + 3, 0);
		world.setBlock(i + 2, j + 8, k + 5, 0);
		world.setBlock(i + 2, j + 8, k + 7, Block.web.blockID);
		world.setBlock(i + 2, j + 8, k + 10, 0);
		world.setBlock(i + 2, j + 8, k + 11, 0);
		world.setBlock(i + 2, j + 8, k + 12, 0);
		world.setBlock(i + 2, j + 9, k + 0, 0);
		world.setBlock(i + 2, j + 9, k + 3, 0);
		world.setBlock(i + 2, j + 9, k + 4, 0);
		world.setBlock(i + 2, j + 9, k + 5, 0);
		world.setBlock(i + 2, j + 9, k + 6, Block.stoneBrick.blockID);
		world.setBlock(i + 2, j + 9, k + 8, 0);
		world.setBlock(i + 2, j + 9, k + 9, 0);
		world.setBlock(i + 2, j + 9, k + 10, Block.web.blockID);
		world.setBlock(i + 2, j + 9, k + 12, 0);
		world.setBlock(i + 2, j + 10, k + 0, 0);
		world.setBlock(i + 2, j + 10, k + 1, 0);
		world.setBlock(i + 2, j + 10, k + 2, 0);
		world.setBlock(i + 2, j + 10, k + 3, 0);
		world.setBlock(i + 2, j + 10, k + 4, Block.web.blockID);
		world.setBlock(i + 2, j + 10, k + 5, Block.stoneBrick.blockID);
		world.setBlock(i + 2, j + 10, k + 6, Block.stoneBrick.blockID);
		world.setBlock(i + 2, j + 10, k + 7, Block.stoneBrick.blockID);
		world.setBlock(i + 2, j + 10, k + 8, 0);
		world.setBlock(i + 2, j + 10, k + 9, 0);
		world.setBlock(i + 2, j + 10, k + 11, 0);
		world.setBlock(i + 2, j + 10, k + 12, 0);
		world.setBlock(i + 2, j + 11, k + 0, 0);
		world.setBlock(i + 2, j + 11, k + 1, Block.web.blockID);
		world.setBlock(i + 2, j + 11, k + 2, 0);
		world.setBlock(i + 2, j + 11, k + 4, Block.stoneBrick.blockID);
		world.setBlock(i + 2, j + 11, k + 5, Block.stoneBrick.blockID);
		world.setBlock(i + 2, j + 11, k + 6, Block.stoneBrick.blockID);
		world.setBlock(i + 2, j + 11, k + 7, Block.stoneBrick.blockID);
		world.setBlock(i + 2, j + 11, k + 8, Block.stoneBrick.blockID);
		world.setBlock(i + 2, j + 11, k + 9, Block.web.blockID);
		world.setBlock(i + 2, j + 11, k + 10, 0);
		world.setBlock(i + 2, j + 11, k + 11, Block.web.blockID);
		world.setBlock(i + 2, j + 11, k + 12, 0);
		world.setBlock(i + 2, j + 12, k + 0, 0);
		world.setBlock(i + 2, j + 12, k + 2, 0);
		world.setBlock(i + 2, j + 12, k + 4, Block.stoneBrick.blockID);
		world.setBlock(i + 2, j + 12, k + 5, 0);
		world.setBlock(i + 2, j + 12, k + 6, Block.web.blockID);
		world.setBlock(i + 2, j + 12, k + 7, 0);
		world.setBlock(i + 2, j + 12, k + 8, Block.stoneBrick.blockID);
		world.setBlock(i + 2, j + 12, k + 9, 0);
		world.setBlock(i + 2, j + 12, k + 10, 0);
		world.setBlock(i + 2, j + 12, k + 11, 0);
		world.setBlock(i + 2, j + 12, k + 12, 0);
		world.setBlock(i + 2, j + 13, k + 0, 0);
		world.setBlock(i + 2, j + 13, k + 2, 0);
		world.setBlock(i + 2, j + 13, k + 3, Block.web.blockID);
		world.setBlock(i + 2, j + 13, k + 4, Block.stoneBrick.blockID);
		world.setBlock(i + 2, j + 13, k + 6, 0);
		world.setBlock(i + 2, j + 13, k + 7, 0);
		world.setBlock(i + 2, j + 13, k + 8, Block.stoneBrick.blockID);
		world.setBlock(i + 2, j + 13, k + 9, 0);
		world.setBlock(i + 2, j + 13, k + 10, 0);
		world.setBlock(i + 2, j + 13, k + 11, 0);
		world.setBlock(i + 2, j + 13, k + 12, 0);
		world.setBlock(i + 2, j + 14, k + 0, 0);
		world.setBlock(i + 2, j + 14, k + 2, 0);
		world.setBlock(i + 2, j + 14, k + 3, Block.web.blockID);
		world.setBlock(i + 2, j + 14, k + 4, Block.stoneBrick.blockID);
		world.setBlock(i + 2, j + 14, k + 5, Block.stoneBrick.blockID);
		world.setBlock(i + 2, j + 14, k + 6, Block.stoneBrick.blockID);
		world.setBlock(i + 2, j + 14, k + 7, Block.stoneBrick.blockID);
		world.setBlock(i + 2, j + 14, k + 8, Block.stoneBrick.blockID);
		world.setBlock(i + 2, j + 14, k + 9, 0);
		world.setBlock(i + 2, j + 14, k + 10, 0);
		world.setBlock(i + 2, j + 14, k + 11, 0);
		world.setBlock(i + 2, j + 14, k + 12, 0);
		world.setBlock(i + 2, j + 15, k + 0, 0);
		world.setBlock(i + 2, j + 15, k + 1, 0);
		world.setBlock(i + 2, j + 15, k + 2, 0);
		world.setBlock(i + 2, j + 15, k + 3, 0);
		world.setBlock(i + 2, j + 15, k + 5, Block.stoneBrick.blockID);
		world.setBlock(i + 2, j + 15, k + 6, Block.stoneBrick.blockID);
		world.setBlock(i + 2, j + 15, k + 7, Block.stoneBrick.blockID);
		world.setBlock(i + 2, j + 15, k + 9, Block.web.blockID);
		world.setBlock(i + 2, j + 15, k + 10, 0);
		world.setBlock(i + 2, j + 15, k + 11, 0);
		world.setBlock(i + 2, j + 15, k + 12, 0);
		world.setBlock(i + 2, j + 16, k + 0, 0);
		world.setBlock(i + 2, j + 16, k + 1, 0);
		world.setBlock(i + 2, j + 16, k + 2, 0);
		world.setBlock(i + 2, j + 16, k + 3, 0);
		world.setBlock(i + 2, j + 16, k + 4, 0);
		world.setBlock(i + 2, j + 16, k + 5, 0);
		world.setBlock(i + 2, j + 16, k + 6, Block.stoneBrick.blockID);
		world.setBlock(i + 2, j + 16, k + 7, 0);
		world.setBlock(i + 2, j + 16, k + 8, 0);
		world.setBlock(i + 2, j + 16, k + 9, 0);
		world.setBlock(i + 2, j + 16, k + 10, 0);
		world.setBlock(i + 2, j + 16, k + 11, 0);
		world.setBlock(i + 2, j + 16, k + 12, 0);
		world.setBlock(i + 2, j + 17, k + 0, 0);
		world.setBlock(i + 2, j + 17, k + 1, 0);
		world.setBlock(i + 2, j + 17, k + 2, 0);
		world.setBlock(i + 2, j + 17, k + 3, 0);
		world.setBlock(i + 2, j + 17, k + 4, 0);
		world.setBlock(i + 2, j + 17, k + 5, 0);
		world.setBlock(i + 2, j + 17, k + 6, 0);
		world.setBlock(i + 2, j + 17, k + 7, 0);
		world.setBlock(i + 2, j + 17, k + 8, 0);
		world.setBlock(i + 2, j + 17, k + 9, 0);
		world.setBlock(i + 2, j + 17, k + 10, 0);
		world.setBlock(i + 2, j + 17, k + 11, 0);
		world.setBlock(i + 2, j + 17, k + 12, 0);
		world.setBlock(i + 2, j + 18, k + 0, 0);
		world.setBlock(i + 2, j + 18, k + 1, 0);
		world.setBlock(i + 2, j + 18, k + 2, 0);
		world.setBlock(i + 2, j + 18, k + 3, 0);
		world.setBlock(i + 2, j + 18, k + 4, 0);
		world.setBlock(i + 2, j + 18, k + 5, 0);
		world.setBlock(i + 2, j + 18, k + 6, 0);
		world.setBlock(i + 2, j + 18, k + 7, 0);
		world.setBlock(i + 2, j + 18, k + 8, 0);
		world.setBlock(i + 2, j + 18, k + 9, 0);
		world.setBlock(i + 2, j + 18, k + 10, 0);
		world.setBlock(i + 2, j + 18, k + 11, 0);
		world.setBlock(i + 2, j + 18, k + 12, 0);
		world.setBlock(i + 2, j + 19, k + 0, 0);
		world.setBlock(i + 2, j + 19, k + 1, 0);
		world.setBlock(i + 2, j + 19, k + 2, 0);
		world.setBlock(i + 2, j + 19, k + 3, 0);
		world.setBlock(i + 2, j + 19, k + 4, 0);
		world.setBlock(i + 2, j + 19, k + 5, 0);
		world.setBlock(i + 2, j + 19, k + 6, 0);
		world.setBlock(i + 2, j + 19, k + 7, 0);
		world.setBlock(i + 2, j + 19, k + 8, 0);
		world.setBlock(i + 2, j + 19, k + 9, 0);
		world.setBlock(i + 2, j + 19, k + 10, 0);
		world.setBlock(i + 2, j + 19, k + 11, 0);
		world.setBlock(i + 2, j + 19, k + 12, 0);
		world.setBlock(i + 3, j + 0, k + 0, 0);
		world.setBlock(i + 3, j + 0, k + 1, Block.stone.blockID);
		world.setBlock(i + 3, j + 0, k + 2, Block.stone.blockID);
		world.setBlock(i + 3, j + 0, k + 3, Block.stone.blockID);
		world.setBlock(i + 3, j + 0, k + 4, Block.stone.blockID);
		world.setBlock(i + 3, j + 0, k + 5, Block.stone.blockID);
		world.setBlock(i + 3, j + 0, k + 6, Block.stone.blockID);
		world.setBlock(i + 3, j + 0, k + 7, Block.stone.blockID);
		world.setBlock(i + 3, j + 0, k + 8, Block.stone.blockID);
		world.setBlock(i + 3, j + 0, k + 9, Block.stone.blockID);
		world.setBlock(i + 3, j + 0, k + 10, Block.stone.blockID);
		world.setBlock(i + 3, j + 0, k + 11, Block.stone.blockID);
		world.setBlock(i + 3, j + 0, k + 12, 0);
		world.setBlock(i + 3, j + 1, k + 0, 0);
		world.setBlock(i + 3, j + 1, k + 1, Block.stone.blockID);
		world.setBlock(i + 3, j + 1, k + 2, Block.stone.blockID);
		world.setBlock(i + 3, j + 1, k + 3, Block.stone.blockID);
		world.setBlock(i + 3, j + 1, k + 4, Block.stone.blockID);
		world.setBlock(i + 3, j + 1, k + 5, Block.stone.blockID);
		world.setBlock(i + 3, j + 1, k + 6, Block.stone.blockID);
		world.setBlock(i + 3, j + 1, k + 7, Block.stone.blockID);
		world.setBlock(i + 3, j + 1, k + 8, Block.stone.blockID);
		world.setBlock(i + 3, j + 1, k + 9, Block.stone.blockID);
		world.setBlock(i + 3, j + 1, k + 10, Block.stone.blockID);
		world.setBlock(i + 3, j + 1, k + 11, Block.stone.blockID);
		world.setBlock(i + 3, j + 1, k + 12, 0);
		world.setBlock(i + 3, j + 2, k + 1, Block.stone.blockID);
		world.setBlock(i + 3, j + 2, k + 2, Block.stone.blockID);
		world.setBlock(i + 3, j + 2, k + 3, Block.stone.blockID);
		world.setBlock(i + 3, j + 2, k + 4, Block.glass.blockID);
		world.setBlock(i + 3, j + 2, k + 5, Block.glass.blockID);
		world.setBlock(i + 3, j + 2, k + 6, Block.glass.blockID);
		world.setBlock(i + 3, j + 2, k + 7, Block.glass.blockID);
		world.setBlock(i + 3, j + 2, k + 8, Block.glass.blockID);
		world.setBlock(i + 3, j + 2, k + 9, Block.stone.blockID);
		world.setBlock(i + 3, j + 2, k + 10, Block.stone.blockID);
		world.setBlock(i + 3, j + 2, k + 11, Block.stone.blockID);
		world.setBlock(i + 3, j + 2, k + 12, 0);
		world.setBlock(i + 3, j + 3, k + 1, Block.stone.blockID);
		world.setBlock(i + 3, j + 3, k + 2, Block.stone.blockID);
		world.setBlock(i + 3, j + 3, k + 3, Block.stone.blockID);
		world.setBlock(i + 3, j + 3, k + 4, Block.glass.blockID);
		world.setBlock(i + 3, j + 3, k + 5, Block.glass.blockID);
		world.setBlock(i + 3, j + 3, k + 6, 0);
		world.setBlock(i + 3, j + 3, k + 7, Block.glass.blockID);
		world.setBlock(i + 3, j + 3, k + 8, Block.glass.blockID);
		world.setBlock(i + 3, j + 3, k + 9, Block.stone.blockID);
		world.setBlock(i + 3, j + 3, k + 10, Block.stone.blockID);
		world.setBlock(i + 3, j + 3, k + 11, Block.stone.blockID);
		world.setBlock(i + 3, j + 3, k + 12, 0);
		world.setBlock(i + 3, j + 4, k + 1, Block.stone.blockID);
		world.setBlock(i + 3, j + 4, k + 2, Block.stone.blockID);
		world.setBlock(i + 3, j + 4, k + 3, Block.stone.blockID);
		world.setBlock(i + 3, j + 4, k + 4, Block.stone.blockID);
		world.setBlock(i + 3, j + 4, k + 5, Block.stone.blockID);
		world.setBlock(i + 3, j + 4, k + 6, Block.stone.blockID);
		world.setBlock(i + 3, j + 4, k + 7, Block.stone.blockID);
		world.setBlock(i + 3, j + 4, k + 8, Block.stone.blockID);
		world.setBlock(i + 3, j + 4, k + 9, Block.stone.blockID);
		world.setBlock(i + 3, j + 4, k + 10, Block.stone.blockID);
		world.setBlock(i + 3, j + 4, k + 11, Block.stone.blockID);
		world.setBlock(i + 3, j + 4, k + 12, 0);
		world.setBlock(i + 3, j + 5, k + 1, Block.stoneBrick.blockID);
		world.setBlock(i + 3, j + 5, k + 2, Block.stoneBrick.blockID);
		world.setBlock(i + 3, j + 5, k + 3, Block.stoneBrick.blockID);
		world.setBlock(i + 3, j + 5, k + 4, Block.stoneBrick.blockID);
		world.setBlock(i + 3, j + 5, k + 5, Block.stoneBrick.blockID);
		world.setBlock(i + 3, j + 5, k + 6, Block.stoneBrick.blockID);
		world.setBlock(i + 3, j + 5, k + 7, Block.stoneBrick.blockID);
		world.setBlock(i + 3, j + 5, k + 8, Block.stoneBrick.blockID);
		world.setBlock(i + 3, j + 5, k + 9, Block.stoneBrick.blockID);
		world.setBlock(i + 3, j + 5, k + 10, Block.stoneBrick.blockID);
		world.setBlock(i + 3, j + 5, k + 11, Block.stoneBrick.blockID);
		world.setBlock(i + 3, j + 5, k + 12, 0);
		world.setBlock(i + 3, j + 6, k + 1, Block.stone.blockID);
		world.setBlock(i + 3, j + 6, k + 2, Block.stone.blockID);
		world.setBlock(i + 3, j + 6, k + 3, Block.stone.blockID);
		world.setBlock(i + 3, j + 6, k + 4, Block.stone.blockID);
		world.setBlock(i + 3, j + 6, k + 5, Block.stone.blockID);
		world.setBlock(i + 3, j + 6, k + 6, Block.stone.blockID);
		world.setBlock(i + 3, j + 6, k + 7, Block.stone.blockID);
		world.setBlock(i + 3, j + 6, k + 8, Block.stone.blockID);
		world.setBlock(i + 3, j + 6, k + 9, Block.stone.blockID);
		world.setBlock(i + 3, j + 6, k + 10, Block.stone.blockID);
		world.setBlock(i + 3, j + 6, k + 11, Block.stone.blockID);
		world.setBlock(i + 3, j + 7, k + 1, Block.stone.blockID);
		world.setBlock(i + 3, j + 7, k + 2, Block.stone.blockID);
		world.setBlock(i + 3, j + 7, k + 3, Block.stone.blockID);
		world.setBlock(i + 3, j + 7, k + 4, Block.stone.blockID);
		world.setBlock(i + 3, j + 7, k + 5, Block.stone.blockID);
		world.setBlock(i + 3, j + 7, k + 6, Block.stone.blockID);
		world.setBlock(i + 3, j + 7, k + 7, Block.stone.blockID);
		world.setBlock(i + 3, j + 7, k + 8, Block.stone.blockID);
		world.setBlock(i + 3, j + 7, k + 9, Block.stone.blockID);
		world.setBlock(i + 3, j + 7, k + 10, Block.stone.blockID);
		world.setBlock(i + 3, j + 7, k + 11, Block.stone.blockID);
		world.setBlock(i + 3, j + 8, k + 1, Block.stone.blockID);
		world.setBlock(i + 3, j + 8, k + 2, Block.stone.blockID);
		world.setBlock(i + 3, j + 8, k + 3, Block.stone.blockID);
		world.setBlock(i + 3, j + 8, k + 4, Block.stone.blockID);
		world.setBlock(i + 3, j + 8, k + 5, Block.stone.blockID);
		world.setBlock(i + 3, j + 8, k + 6, Block.stone.blockID);
		world.setBlock(i + 3, j + 8, k + 7, Block.stone.blockID);
		world.setBlock(i + 3, j + 8, k + 8, Block.stone.blockID);
		world.setBlock(i + 3, j + 8, k + 9, Block.stone.blockID);
		world.setBlock(i + 3, j + 8, k + 10, Block.stone.blockID);
		world.setBlock(i + 3, j + 8, k + 11, Block.stone.blockID);
		world.setBlock(i + 3, j + 8, k + 12, 0);
		world.setBlock(i + 3, j + 9, k + 0, 0);
		world.setBlock(i + 3, j + 9, k + 1, Block.stone.blockID);
		world.setBlock(i + 3, j + 9, k + 2, Block.stone.blockID);
		world.setBlock(i + 3, j + 9, k + 3, Block.stone.blockID);
		world.setBlock(i + 3, j + 9, k + 4, Block.stone.blockID);
		world.setBlock(i + 3, j + 9, k + 5, Block.stone.blockID);
		world.setBlock(i + 3, j + 9, k + 6, Block.stone.blockID);
		world.setBlock(i + 3, j + 9, k + 7, Block.stone.blockID);
		world.setBlock(i + 3, j + 9, k + 8, Block.stone.blockID);
		world.setBlock(i + 3, j + 9, k + 9, Block.stone.blockID);
		world.setBlock(i + 3, j + 9, k + 10, Block.stone.blockID);
		world.setBlock(i + 3, j + 9, k + 11, Block.stone.blockID);
		world.setBlock(i + 3, j + 9, k + 12, 0);
		world.setBlock(i + 3, j + 10, k + 0, 0);
		world.setBlock(i + 3, j + 10, k + 1, Block.stone.blockID);
		world.setBlock(i + 3, j + 10, k + 2, Block.stone.blockID);
		world.setBlock(i + 3, j + 10, k + 3, Block.stone.blockID);
		world.setBlock(i + 3, j + 10, k + 4, Block.stone.blockID);
		world.setBlock(i + 3, j + 10, k + 5, Block.stone.blockID);
		world.setBlock(i + 3, j + 10, k + 6, Block.stone.blockID);
		world.setBlock(i + 3, j + 10, k + 7, Block.stone.blockID);
		world.setBlock(i + 3, j + 10, k + 8, Block.stone.blockID);
		world.setBlock(i + 3, j + 10, k + 9, Block.stone.blockID);
		world.setBlock(i + 3, j + 10, k + 10, Block.stone.blockID);
		world.setBlock(i + 3, j + 10, k + 11, Block.stone.blockID);
		world.setBlock(i + 3, j + 10, k + 12, 0);
		world.setBlock(i + 3, j + 11, k + 1, Block.stone.blockID);
		world.setBlock(i + 3, j + 11, k + 2, Block.stone.blockID);
		world.setBlock(i + 3, j + 11, k + 3, Block.stone.blockID);
		world.setBlock(i + 3, j + 11, k + 4, Block.stone.blockID);
		world.setBlock(i + 3, j + 11, k + 5, Block.stoneBrick.blockID);
		world.setBlock(i + 3, j + 11, k + 6, Block.stoneBrick.blockID);
		world.setBlock(i + 3, j + 11, k + 7, Block.stoneBrick.blockID);
		world.setBlock(i + 3, j + 11, k + 8, Block.stone.blockID);
		world.setBlock(i + 3, j + 11, k + 9, Block.stone.blockID);
		world.setBlock(i + 3, j + 11, k + 10, Block.stone.blockID);
		world.setBlock(i + 3, j + 11, k + 11, Block.stone.blockID);
		world.setBlock(i + 3, j + 11, k + 12, Block.web.blockID);
		world.setBlock(i + 3, j + 12, k + 1, Block.stoneBrick.blockID);
		world.setBlock(i + 3, j + 12, k + 2, Block.stoneBrick.blockID);
		world.setBlock(i + 3, j + 12, k + 3, Block.stoneBrick.blockID);
		world.setBlock(i + 3, j + 12, k + 4, Block.stoneBrick.blockID);
		world.setBlock(i + 3, j + 12, k + 5, Block.web.blockID);
		world.setBlock(i + 3, j + 12, k + 6, 0);
		world.setBlock(i + 3, j + 12, k + 7, Block.web.blockID);
		world.setBlock(i + 3, j + 12, k + 8, Block.stoneBrick.blockID);
		world.setBlock(i + 3, j + 12, k + 9, Block.stoneBrick.blockID);
		world.setBlock(i + 3, j + 12, k + 10, Block.stoneBrick.blockID);
		world.setBlock(i + 3, j + 12, k + 11, Block.stoneBrick.blockID);
		world.setBlock(i + 3, j + 12, k + 12, 0);
		world.setBlock(i + 3, j + 13, k + 0, 0);
		world.setBlock(i + 3, j + 13, k + 1, Block.stoneBrick.blockID);
		world.setBlock(i + 3, j + 13, k + 2, Block.stoneBrick.blockID);
		world.setBlockMetadataWithNotify(i + 3, j + 13, k + 3, Block.stoneBrick.blockID, 1);
		world.setBlockMetadataWithNotify(i + 3, j + 13, k + 4, Block.stoneBrick.blockID, 1);
		world.setBlock(i + 3, j + 13, k + 6, 0);
		world.setBlock(i + 3, j + 13, k + 7, Block.web.blockID);
		world.setBlock(i + 3, j + 13, k + 8, Block.stoneBrick.blockID);
		world.setBlock(i + 3, j + 13, k + 9, Block.stoneBrick.blockID);
		world.setBlockMetadataWithNotify(i + 3, j + 13, k + 10, Block.stoneBrick.blockID, 1);
		world.setBlock(i + 3, j + 13, k + 11, Block.stoneBrick.blockID);
		world.setBlock(i + 3, j + 13, k + 12, 0);
		world.setBlock(i + 3, j + 14, k + 1, Block.stoneBrick.blockID);
		world.setBlock(i + 3, j + 14, k + 2, Block.stoneBrick.blockID);
		world.setBlock(i + 3, j + 14, k + 3, Block.stoneBrick.blockID);
		world.setBlock(i + 3, j + 14, k + 4, Block.stoneBrick.blockID);
		world.setBlock(i + 3, j + 14, k + 5, Block.stoneBrick.blockID);
		world.setBlock(i + 3, j + 14, k + 6, Block.stoneBrick.blockID);
		world.setBlock(i + 3, j + 14, k + 7, Block.stoneBrick.blockID);
		world.setBlock(i + 3, j + 14, k + 8, Block.stoneBrick.blockID);
		world.setBlock(i + 3, j + 14, k + 9, Block.stoneBrick.blockID);
		world.setBlock(i + 3, j + 14, k + 10, Block.stoneBrick.blockID);
		world.setBlock(i + 3, j + 14, k + 11, Block.stoneBrick.blockID);
		world.setBlock(i + 3, j + 14, k + 12, 0);
		world.setBlock(i + 3, j + 15, k + 0, 0);
		world.setBlock(i + 3, j + 15, k + 1, 0);
		world.setBlock(i + 3, j + 15, k + 2, Block.web.blockID);
		world.setBlock(i + 3, j + 15, k + 3, 0);
		world.setBlock(i + 3, j + 15, k + 4, Block.stoneBrick.blockID);
		world.setBlock(i + 3, j + 15, k + 5, Block.stoneBrick.blockID);
		world.setBlock(i + 3, j + 15, k + 6, Block.stoneBrick.blockID);
		world.setBlock(i + 3, j + 15, k + 7, Block.stoneBrick.blockID);
		world.setBlock(i + 3, j + 15, k + 8, Block.stoneBrick.blockID);
		world.setBlock(i + 3, j + 15, k + 9, Block.web.blockID);
		world.setBlock(i + 3, j + 15, k + 10, 0);
		world.setBlock(i + 3, j + 15, k + 11, 0);
		world.setBlock(i + 3, j + 15, k + 12, 0);
		world.setBlock(i + 3, j + 16, k + 0, 0);
		world.setBlock(i + 3, j + 16, k + 1, 0);
		world.setBlock(i + 3, j + 16, k + 2, 0);
		world.setBlock(i + 3, j + 16, k + 3, Block.web.blockID);
		world.setBlock(i + 3, j + 16, k + 5, 0);
		world.setBlock(i + 3, j + 16, k + 6, Block.stoneBrick.blockID);
		world.setBlock(i + 3, j + 16, k + 7, Block.web.blockID);
		world.setBlock(i + 3, j + 16, k + 8, 0);
		world.setBlock(i + 3, j + 16, k + 9, 0);
		world.setBlock(i + 3, j + 16, k + 10, 0);
		world.setBlock(i + 3, j + 16, k + 11, 0);
		world.setBlock(i + 3, j + 16, k + 12, 0);
		world.setBlock(i + 3, j + 17, k + 0, 0);
		world.setBlock(i + 3, j + 17, k + 1, 0);
		world.setBlock(i + 3, j + 17, k + 2, 0);
		world.setBlock(i + 3, j + 17, k + 3, 0);
		world.setBlock(i + 3, j + 17, k + 4, 0);
		world.setBlock(i + 3, j + 17, k + 6, 0);
		world.setBlock(i + 3, j + 17, k + 8, 0);
		world.setBlock(i + 3, j + 17, k + 9, 0);
		world.setBlock(i + 3, j + 17, k + 10, 0);
		world.setBlock(i + 3, j + 17, k + 11, 0);
		world.setBlock(i + 3, j + 17, k + 12, 0);
		world.setBlock(i + 3, j + 18, k + 0, 0);
		world.setBlock(i + 3, j + 18, k + 1, 0);
		world.setBlock(i + 3, j + 18, k + 2, 0);
		world.setBlock(i + 3, j + 18, k + 3, 0);
		world.setBlock(i + 3, j + 18, k + 4, 0);
		world.setBlock(i + 3, j + 18, k + 8, 0);
		world.setBlock(i + 3, j + 18, k + 9, 0);
		world.setBlock(i + 3, j + 18, k + 10, 0);
		world.setBlock(i + 3, j + 18, k + 11, 0);
		world.setBlock(i + 3, j + 18, k + 12, 0);
		world.setBlock(i + 3, j + 19, k + 0, 0);
		world.setBlock(i + 3, j + 19, k + 1, 0);
		world.setBlock(i + 3, j + 19, k + 2, 0);
		world.setBlock(i + 3, j + 19, k + 3, 0);
		world.setBlock(i + 3, j + 19, k + 4, 0);
		world.setBlock(i + 3, j + 19, k + 5, 0);
		world.setBlock(i + 3, j + 19, k + 6, 0);
		world.setBlock(i + 3, j + 19, k + 7, 0);
		world.setBlock(i + 3, j + 19, k + 8, 0);
		world.setBlock(i + 3, j + 19, k + 9, 0);
		world.setBlock(i + 3, j + 19, k + 10, 0);
		world.setBlock(i + 3, j + 19, k + 11, 0);
		world.setBlock(i + 3, j + 19, k + 12, 0);
		world.setBlock(i + 4, j + 0, k + 0, 0);
		world.setBlock(i + 4, j + 0, k + 1, Block.stone.blockID);
		world.setBlock(i + 4, j + 0, k + 2, Block.cloth.blockID);
		world.setBlock(i + 4, j + 0, k + 3, Block.cloth.blockID);
		world.setBlock(i + 4, j + 0, k + 4, Block.cloth.blockID);
		world.setBlock(i + 4, j + 0, k + 5, Block.cloth.blockID);
		world.setBlockMetadataWithNotify(i + 4, j + 0, k + 6, Block.cloth.blockID, 14);
		world.setBlock(i + 4, j + 0, k + 7, Block.cloth.blockID);
		world.setBlock(i + 4, j + 0, k + 8, Block.cloth.blockID);
		world.setBlock(i + 4, j + 0, k + 9, Block.cloth.blockID);
		world.setBlock(i + 4, j + 0, k + 10, Block.cloth.blockID);
		world.setBlock(i + 4, j + 0, k + 11, Block.stone.blockID);
		world.setBlock(i + 4, j + 0, k + 12, 0);
		world.setBlock(i + 4, j + 1, k + 0, 0);
		world.setBlock(i + 4, j + 1, k + 1, Block.stone.blockID);
		world.setBlock(i + 4, j + 1, k + 2, Block.glowStone.blockID);
		world.setBlock(i + 4, j + 1, k + 3, Block.glowStone.blockID);
		world.setBlockMetadataWithNotify(i + 4, j + 1, k + 4, Block.chest.blockID, 5);
		world.setBlockMetadataWithNotify(i + 4, j + 1, k + 5, Block.chest.blockID, 5);
		world.setBlock(i + 4, j + 1, k + 6, Block.workbench.blockID);
		world.setBlockMetadataWithNotify(i + 4, j + 1, k + 7, Block.chest.blockID, 5);
		world.setBlockMetadataWithNotify(i + 4, j + 1, k + 8, Block.chest.blockID, 5);
		world.setBlock(i + 4, j + 1, k + 9, Block.glowStone.blockID);
		world.setBlock(i + 4, j + 1, k + 10, Block.glowStone.blockID);
		world.setBlock(i + 4, j + 1, k + 11, Block.stone.blockID);
		world.setBlock(i + 4, j + 1, k + 12, 0);
		world.setBlock(i + 4, j + 2, k + 0, 0);
		world.setBlock(i + 4, j + 2, k + 1, Block.stone.blockID);
		world.setBlock(i + 4, j + 2, k + 2, Block.glowStone.blockID);
		world.setBlock(i + 4, j + 2, k + 3, Block.glowStone.blockID);
		world.setBlock(i + 4, j + 2, k + 4, 0);
		world.setBlock(i + 4, j + 2, k + 5, Block.web.blockID);
		world.setBlock(i + 4, j + 2, k + 6, 0);
		world.setBlock(i + 4, j + 2, k + 7, Block.web.blockID);
		world.setBlock(i + 4, j + 2, k + 8, 0);
		world.setBlock(i + 4, j + 2, k + 9, Block.glowStone.blockID);
		world.setBlock(i + 4, j + 2, k + 10, Block.glowStone.blockID);
		world.setBlock(i + 4, j + 2, k + 11, Block.stone.blockID);
		world.setBlock(i + 4, j + 2, k + 12, 0);
		world.setBlock(i + 4, j + 3, k + 0, 0);
		world.setBlock(i + 4, j + 3, k + 1, Block.stone.blockID);
		world.setBlock(i + 4, j + 3, k + 2, Block.glowStone.blockID);
		world.setBlock(i + 4, j + 3, k + 3, Block.glowStone.blockID);
		world.setBlock(i + 4, j + 3, k + 4, 0);
		world.setBlock(i + 4, j + 3, k + 6, 0);
		world.setBlock(i + 4, j + 3, k + 8, 0);
		world.setBlock(i + 4, j + 3, k + 9, Block.web.blockID);
		world.setBlock(i + 4, j + 3, k + 10, Block.glowStone.blockID);
		world.setBlock(i + 4, j + 3, k + 11, Block.stone.blockID);
		world.setBlock(i + 4, j + 3, k + 12, 0);
		world.setBlock(i + 4, j + 4, k + 1, Block.stone.blockID);
		world.setBlock(i + 4, j + 4, k + 2, Block.blockDiamond.blockID);
		world.setBlock(i + 4, j + 4, k + 3, Block.glowStone.blockID);
		world.setBlock(i + 4, j + 4, k + 4, 0);
		world.setBlock(i + 4, j + 4, k + 6, 0);
		world.setBlock(i + 4, j + 4, k + 8, 0);
		world.setBlock(i + 4, j + 4, k + 9, Block.glowStone.blockID);
		world.setBlock(i + 4, j + 4, k + 10, Block.glowStone.blockID);
		world.setBlock(i + 4, j + 4, k + 11, Block.stone.blockID);
		world.setBlock(i + 4, j + 4, k + 12, 0);
		world.setBlock(i + 4, j + 5, k + 0, 0);
		world.setBlock(i + 4, j + 5, k + 1, Block.stoneBrick.blockID);
		world.setBlock(i + 4, j + 5, k + 2, Block.stoneBrick.blockID);
		world.setBlock(i + 4, j + 5, k + 3, Block.stoneBrick.blockID);
		world.setBlock(i + 4, j + 5, k + 4, Block.stoneBrick.blockID);
		world.setBlock(i + 4, j + 5, k + 5, Block.stoneBrick.blockID);
		world.setBlock(i + 4, j + 5, k + 6, Block.stoneBrick.blockID);
		world.setBlock(i + 4, j + 5, k + 7, Block.stoneBrick.blockID);
		world.setBlock(i + 4, j + 5, k + 8, Block.stoneBrick.blockID);
		world.setBlock(i + 4, j + 5, k + 9, Block.stoneBrick.blockID);
		world.setBlock(i + 4, j + 5, k + 10, Block.stoneBrick.blockID);
		world.setBlock(i + 4, j + 5, k + 11, Block.stoneBrick.blockID);
		world.setBlock(i + 4, j + 6, k + 0, 0);
		world.setBlock(i + 4, j + 6, k + 1, Block.stone.blockID);
		world.setBlock(i + 4, j + 6, k + 2, 0);
		world.setBlock(i + 4, j + 6, k + 3, 0);
		world.setBlock(i + 4, j + 6, k + 4, Block.web.blockID);
		world.setBlock(i + 4, j + 6, k + 6, 0);
		world.setBlock(i + 4, j + 6, k + 7, 0);
		world.setBlock(i + 4, j + 6, k + 8, Block.web.blockID);
		world.setBlock(i + 4, j + 6, k + 9, 0);
		world.setBlock(i + 4, j + 6, k + 11, Block.stone.blockID);
		world.setBlock(i + 4, j + 7, k + 0, Block.web.blockID);
		world.setBlock(i + 4, j + 7, k + 1, Block.stone.blockID);
		world.setBlock(i + 4, j + 7, k + 2, 0);
		world.setBlock(i + 4, j + 7, k + 3, 0);
		world.setBlock(i + 4, j + 7, k + 4, 0);
		world.setBlock(i + 4, j + 7, k + 6, 0);
		world.setBlock(i + 4, j + 7, k + 7, 0);
		world.setBlock(i + 4, j + 7, k + 8, Block.web.blockID);
		world.setBlock(i + 4, j + 7, k + 11, Block.stone.blockID);
		world.setBlock(i + 4, j + 8, k + 1, Block.stone.blockID);
		world.setBlock(i + 4, j + 8, k + 2, 0);
		world.setBlock(i + 4, j + 8, k + 3, 0);
		world.setBlock(i + 4, j + 8, k + 4, 0);
		world.setBlock(i + 4, j + 8, k + 5, Block.web.blockID);
		world.setBlock(i + 4, j + 8, k + 7, Block.web.blockID);
		world.setBlock(i + 4, j + 8, k + 8, Block.web.blockID);
		world.setBlock(i + 4, j + 8, k + 11, Block.stone.blockID);
		world.setBlock(i + 4, j + 9, k + 1, Block.stone.blockID);
		world.setBlock(i + 4, j + 9, k + 2, 0);
		world.setBlock(i + 4, j + 9, k + 3, Block.web.blockID);
		world.setBlock(i + 4, j + 9, k + 5, Block.web.blockID);
		world.setBlock(i + 4, j + 9, k + 6, 0);
		world.setBlock(i + 4, j + 9, k + 7, Block.web.blockID);
		world.setBlock(i + 4, j + 9, k + 8, Block.web.blockID);
		world.setBlock(i + 4, j + 9, k + 11, Block.stone.blockID);
		world.setBlock(i + 4, j + 9, k + 12, 0);
		world.setBlock(i + 4, j + 10, k + 0, 0);
		world.setBlock(i + 4, j + 10, k + 1, Block.stone.blockID);
		world.setBlock(i + 4, j + 10, k + 2, 0);
		world.setBlock(i + 4, j + 10, k + 3, Block.web.blockID);
		world.setBlock(i + 4, j + 10, k + 4, 0);
		world.setBlock(i + 4, j + 10, k + 5, 0);
		world.setBlock(i + 4, j + 10, k + 6, Block.web.blockID);
		world.setBlock(i + 4, j + 10, k + 7, Block.web.blockID);
		world.setBlock(i + 4, j + 10, k + 8, 0);
		world.setBlock(i + 4, j + 10, k + 10, 0);
		world.setBlock(i + 4, j + 10, k + 11, Block.stone.blockID);
		world.setBlock(i + 4, j + 10, k + 12, 0);
		world.setBlock(i + 4, j + 11, k + 0, 0);
		world.setBlock(i + 4, j + 11, k + 1, Block.stone.blockID);
		world.setBlock(i + 4, j + 11, k + 2, Block.stoneBrick.blockID);
		world.setBlock(i + 4, j + 11, k + 3, Block.stoneBrick.blockID);
		world.setBlock(i + 4, j + 11, k + 4, Block.stoneBrick.blockID);
		world.setBlock(i + 4, j + 11, k + 5, Block.stoneBrick.blockID);
		world.setBlock(i + 4, j + 11, k + 6, Block.stoneBrick.blockID);
		world.setBlock(i + 4, j + 11, k + 7, Block.stoneBrick.blockID);
		world.setBlock(i + 4, j + 11, k + 8, Block.stoneBrick.blockID);
		world.setBlock(i + 4, j + 11, k + 9, Block.stoneBrick.blockID);
		world.setBlock(i + 4, j + 11, k + 10, Block.stoneBrick.blockID);
		world.setBlock(i + 4, j + 11, k + 11, Block.stone.blockID);
		world.setBlock(i + 4, j + 11, k + 12, 0);
		world.setBlock(i + 4, j + 12, k + 1, Block.stoneBrick.blockID);
		world.setBlock(i + 4, j + 12, k + 2, 0);
		world.setBlock(i + 4, j + 12, k + 3, 0);
		world.setBlock(i + 4, j + 12, k + 4, 0);
		world.setBlock(i + 4, j + 12, k + 5, Block.web.blockID);
		world.setBlock(i + 4, j + 12, k + 6, Block.web.blockID);
		world.setBlock(i + 4, j + 12, k + 7, Block.web.blockID);
		world.setBlock(i + 4, j + 12, k + 8, 0);
		world.setBlock(i + 4, j + 12, k + 9, 0);
		world.setBlock(i + 4, j + 12, k + 10, 0);
		world.setBlock(i + 4, j + 12, k + 11, Block.stoneBrick.blockID);
		world.setBlock(i + 4, j + 13, k + 1, Block.stoneBrick.blockID);
		world.setBlock(i + 4, j + 13, k + 2, 0);
		world.setBlock(i + 4, j + 13, k + 3, 0);
		world.setBlock(i + 4, j + 13, k + 4, Block.web.blockID);
		world.setBlock(i + 4, j + 13, k + 5, 0);
		world.setBlock(i + 4, j + 13, k + 6, 0);
		world.setBlock(i + 4, j + 13, k + 7, 0);
		world.setBlock(i + 4, j + 13, k + 8, 0);
		world.setBlock(i + 4, j + 13, k + 10, 0);
		world.setBlock(i + 4, j + 13, k + 11, Block.stoneBrick.blockID);
		world.setBlock(i + 4, j + 13, k + 12, 0);
		world.setBlock(i + 4, j + 14, k + 0, 0);
		world.setBlock(i + 4, j + 14, k + 1, Block.stoneBrick.blockID);
		world.setBlock(i + 4, j + 14, k + 2, 0);
		world.setBlock(i + 4, j + 14, k + 3, 0);
		world.setBlock(i + 4, j + 14, k + 4, 0);
		world.setBlock(i + 4, j + 14, k + 5, 0);
		world.setBlock(i + 4, j + 14, k + 6, 0);
		world.setBlock(i + 4, j + 14, k + 7, 0);
		world.setBlock(i + 4, j + 14, k + 8, 0);
		world.setBlock(i + 4, j + 14, k + 9, 0);
		world.setBlock(i + 4, j + 14, k + 10, 0);
		world.setBlock(i + 4, j + 14, k + 11, Block.stoneBrick.blockID);
		world.setBlock(i + 4, j + 14, k + 12, 0);
		world.setBlock(i + 4, j + 15, k + 0, 0);
		world.setBlock(i + 4, j + 15, k + 1, 0);
		world.setBlock(i + 4, j + 15, k + 2, Block.stoneBrick.blockID);
		world.setBlock(i + 4, j + 15, k + 3, Block.stoneBrick.blockID);
		world.setBlock(i + 4, j + 15, k + 4, Block.stoneBrick.blockID);
		world.setBlock(i + 4, j + 15, k + 5, Block.stoneBrick.blockID);
		world.setBlock(i + 4, j + 15, k + 6, Block.stoneBrick.blockID);
		world.setBlock(i + 4, j + 15, k + 7, Block.stoneBrick.blockID);
		world.setBlock(i + 4, j + 15, k + 8, Block.stoneBrick.blockID);
		world.setBlock(i + 4, j + 15, k + 9, Block.stoneBrick.blockID);
		world.setBlock(i + 4, j + 15, k + 10, Block.stoneBrick.blockID);
		world.setBlock(i + 4, j + 15, k + 11, 0);
		world.setBlock(i + 4, j + 15, k + 12, 0);
		world.setBlock(i + 4, j + 16, k + 0, 0);
		world.setBlock(i + 4, j + 16, k + 1, 0);
		world.setBlock(i + 4, j + 16, k + 2, 0);
		world.setBlock(i + 4, j + 16, k + 3, Block.stoneBrick.blockID);
		world.setBlock(i + 4, j + 16, k + 4, Block.stoneBrick.blockID);
		world.setBlock(i + 4, j + 16, k + 5, Block.stoneBrick.blockID);
		world.setBlock(i + 4, j + 16, k + 6, Block.stoneBrick.blockID);
		world.setBlock(i + 4, j + 16, k + 7, Block.stoneBrick.blockID);
		world.setBlock(i + 4, j + 16, k + 8, Block.stoneBrick.blockID);
		world.setBlock(i + 4, j + 16, k + 9, Block.stoneBrick.blockID);
		world.setBlock(i + 4, j + 16, k + 10, 0);
		world.setBlock(i + 4, j + 16, k + 11, 0);
		world.setBlock(i + 4, j + 16, k + 12, 0);
		world.setBlock(i + 4, j + 17, k + 0, 0);
		world.setBlock(i + 4, j + 17, k + 1, 0);
		world.setBlock(i + 4, j + 17, k + 2, 0);
		world.setBlock(i + 4, j + 17, k + 3, 0);
		world.setBlock(i + 4, j + 17, k + 4, Block.stoneBrick.blockID);
		world.setBlock(i + 4, j + 17, k + 5, Block.stoneBrick.blockID);
		world.setBlock(i + 4, j + 17, k + 6, Block.stoneBrick.blockID);
		world.setBlock(i + 4, j + 17, k + 7, Block.stoneBrick.blockID);
		world.setBlock(i + 4, j + 17, k + 8, Block.stoneBrick.blockID);
		world.setBlock(i + 4, j + 17, k + 9, 0);
		world.setBlock(i + 4, j + 17, k + 10, 0);
		world.setBlock(i + 4, j + 17, k + 11, 0);
		world.setBlock(i + 4, j + 17, k + 12, 0);
		world.setBlock(i + 4, j + 18, k + 0, 0);
		world.setBlock(i + 4, j + 18, k + 1, 0);
		world.setBlock(i + 4, j + 18, k + 2, 0);
		world.setBlock(i + 4, j + 18, k + 3, 0);
		world.setBlock(i + 4, j + 18, k + 4, 0);
		world.setBlock(i + 4, j + 18, k + 5, Block.stoneBrick.blockID);
		world.setBlock(i + 4, j + 18, k + 6, Block.stoneBrick.blockID);
		world.setBlock(i + 4, j + 18, k + 7, Block.stoneBrick.blockID);
		world.setBlock(i + 4, j + 18, k + 8, 0);
		world.setBlock(i + 4, j + 18, k + 9, 0);
		world.setBlock(i + 4, j + 18, k + 10, 0);
		world.setBlock(i + 4, j + 18, k + 11, 0);
		world.setBlock(i + 4, j + 18, k + 12, 0);
		world.setBlock(i + 4, j + 19, k + 0, 0);
		world.setBlock(i + 4, j + 19, k + 1, 0);
		world.setBlock(i + 4, j + 19, k + 2, 0);
		world.setBlock(i + 4, j + 19, k + 3, 0);
		world.setBlock(i + 4, j + 19, k + 4, 0);
		world.setBlock(i + 4, j + 19, k + 5, 0);
		world.setBlock(i + 4, j + 19, k + 6, Block.stoneBrick.blockID);
		world.setBlock(i + 4, j + 19, k + 8, 0);
		world.setBlock(i + 4, j + 19, k + 9, 0);
		world.setBlock(i + 4, j + 19, k + 10, 0);
		world.setBlock(i + 4, j + 19, k + 11, 0);
		world.setBlock(i + 4, j + 19, k + 12, 0);
		world.setBlock(i + 5, j + 0, k + 0, 0);
		world.setBlock(i + 5, j + 0, k + 1, Block.stone.blockID);
		world.setBlock(i + 5, j + 0, k + 2, Block.cloth.blockID);
		world.setBlock(i + 5, j + 0, k + 3, Block.cloth.blockID);
		world.setBlock(i + 5, j + 0, k + 4, Block.cloth.blockID);
		world.setBlock(i + 5, j + 0, k + 5, Block.cloth.blockID);
		world.setBlockMetadataWithNotify(i + 5, j + 0, k + 6, Block.cloth.blockID, 14);
		world.setBlock(i + 5, j + 0, k + 7, Block.cloth.blockID);
		world.setBlock(i + 5, j + 0, k + 8, Block.cloth.blockID);
		world.setBlock(i + 5, j + 0, k + 9, Block.cloth.blockID);
		world.setBlock(i + 5, j + 0, k + 10, Block.cloth.blockID);
		world.setBlock(i + 5, j + 0, k + 11, Block.stone.blockID);
		world.setBlock(i + 5, j + 0, k + 12, 0);
		world.setBlock(i + 5, j + 1, k + 0, 0);
		world.setBlock(i + 5, j + 1, k + 1, Block.stone.blockID);
		world.setBlock(i + 5, j + 1, k + 2, Block.glowStone.blockID);
		world.setBlock(i + 5, j + 1, k + 3, Block.glowStone.blockID);
		world.setBlock(i + 5, j + 1, k + 4, Block.web.blockID);
		world.setBlock(i + 5, j + 1, k + 5, 0);
		world.setBlock(i + 5, j + 1, k + 6, 0);
		world.setBlock(i + 5, j + 1, k + 7, 0);
		world.setBlock(i + 5, j + 1, k + 8, Block.web.blockID);
		world.setBlock(i + 5, j + 1, k + 9, Block.glowStone.blockID);
		world.setBlock(i + 5, j + 1, k + 10, Block.glowStone.blockID);
		world.setBlock(i + 5, j + 1, k + 11, Block.stone.blockID);
		world.setBlock(i + 5, j + 1, k + 12, 0);
		world.setBlock(i + 5, j + 2, k + 0, 0);
		world.setBlock(i + 5, j + 2, k + 1, Block.stone.blockID);
		world.setBlock(i + 5, j + 2, k + 2, Block.glowStone.blockID);
		world.setBlock(i + 5, j + 2, k + 3, Block.web.blockID);
		world.setBlock(i + 5, j + 2, k + 5, 0);
		world.setBlock(i + 5, j + 2, k + 6, 0);
		world.setBlock(i + 5, j + 2, k + 7, 0);
		world.setBlock(i + 5, j + 2, k + 8, 0);
		world.setBlock(i + 5, j + 2, k + 9, Block.glowStone.blockID);
		world.setBlock(i + 5, j + 2, k + 10, Block.glowStone.blockID);
		world.setBlock(i + 5, j + 2, k + 11, Block.stone.blockID);
		world.setBlock(i + 5, j + 2, k + 12, 0);
		world.setBlock(i + 5, j + 3, k + 1, Block.stone.blockID);
		world.setBlock(i + 5, j + 3, k + 2, Block.glowStone.blockID);
		world.setBlock(i + 5, j + 3, k + 3, Block.glowStone.blockID);
		world.setBlock(i + 5, j + 3, k + 5, 0);
		world.setBlock(i + 5, j + 3, k + 6, 0);
		world.setBlock(i + 5, j + 3, k + 7, 0);
		world.setBlock(i + 5, j + 3, k + 8, 0);
		world.setBlock(i + 5, j + 3, k + 9, Block.glowStone.blockID);
		world.setBlock(i + 5, j + 3, k + 10, Block.glowStone.blockID);
		world.setBlock(i + 5, j + 3, k + 11, Block.stone.blockID);
		world.setBlock(i + 5, j + 3, k + 12, 0);
		world.setBlock(i + 5, j + 4, k + 0, 0);
		world.setBlock(i + 5, j + 4, k + 1, Block.stone.blockID);
		world.setBlock(i + 5, j + 4, k + 2, Block.stoneBrick.blockID);
		world.setBlock(i + 5, j + 4, k + 3, Block.stoneBrick.blockID);
		world.setBlock(i + 5, j + 4, k + 5, 0);
		world.setBlock(i + 5, j + 4, k + 6, 0);
		world.setBlock(i + 5, j + 4, k + 7, 0);
		world.setBlock(i + 5, j + 4, k + 8, 0);
		world.setBlock(i + 5, j + 4, k + 9, Block.stoneBrick.blockID);
		world.setBlock(i + 5, j + 4, k + 10, Block.stoneBrick.blockID);
		world.setBlock(i + 5, j + 4, k + 11, Block.stone.blockID);
		world.setBlock(i + 5, j + 4, k + 12, 0);
		world.setBlock(i + 5, j + 5, k + 0, 0);
		world.setBlock(i + 5, j + 5, k + 1, Block.stoneBrick.blockID);
		world.setBlock(i + 5, j + 5, k + 2, 0);
		world.setBlock(i + 5, j + 5, k + 3, 0);
		world.setBlock(i + 5, j + 5, k + 4, Block.stoneBrick.blockID);
		world.setBlock(i + 5, j + 5, k + 5, 0);
		world.setBlock(i + 5, j + 5, k + 6, 0);
		world.setBlock(i + 5, j + 5, k + 7, 0);
		world.setBlock(i + 5, j + 5, k + 8, Block.stoneBrick.blockID);
		world.setBlock(i + 5, j + 5, k + 9, 0);
		world.setBlock(i + 5, j + 5, k + 10, 0);
		world.setBlock(i + 5, j + 5, k + 11, Block.stoneBrick.blockID);
		world.setBlock(i + 5, j + 5, k + 12, 0);
		world.setBlock(i + 5, j + 6, k + 0, 0);
		world.setBlock(i + 5, j + 6, k + 1, Block.stone.blockID);
		world.setBlock(i + 5, j + 6, k + 2, 0);
		world.setBlock(i + 5, j + 6, k + 3, 0);
		world.setBlock(i + 5, j + 6, k + 4, 0);
		world.setBlock(i + 5, j + 6, k + 5, Block.stoneBrick.blockID);
		world.setBlock(i + 5, j + 6, k + 6, Block.stoneBrick.blockID);
		world.setBlock(i + 5, j + 6, k + 7, Block.stoneBrick.blockID);
		world.setBlock(i + 5, j + 6, k + 8, 0);
		world.setBlock(i + 5, j + 6, k + 9, 0);
		world.setBlock(i + 5, j + 6, k + 10, 0);
		world.setBlock(i + 5, j + 6, k + 11, Block.stone.blockID);
		world.setBlock(i + 5, j + 6, k + 12, 0);
		world.setBlock(i + 5, j + 7, k + 0, 0);
		world.setBlock(i + 5, j + 7, k + 1, Block.stone.blockID);
		world.setBlock(i + 5, j + 7, k + 2, 0);
		world.setBlock(i + 5, j + 7, k + 3, 0);
		world.setBlock(i + 5, j + 7, k + 4, 0);
		world.setBlock(i + 5, j + 7, k + 7, 0);
		world.setBlock(i + 5, j + 7, k + 8, 0);
		world.setBlock(i + 5, j + 7, k + 9, 0);
		world.setBlock(i + 5, j + 7, k + 10, Block.web.blockID);
		world.setBlock(i + 5, j + 7, k + 11, Block.stone.blockID);
		world.setBlock(i + 5, j + 7, k + 12, 0);
		world.setBlock(i + 5, j + 8, k + 0, 0);
		world.setBlock(i + 5, j + 8, k + 1, Block.stone.blockID);
		world.setBlock(i + 5, j + 8, k + 2, Block.web.blockID);
		world.setBlock(i + 5, j + 8, k + 3, 0);
		world.setBlock(i + 5, j + 8, k + 4, 0);
		world.setBlock(i + 5, j + 8, k + 5, 0);
		world.setBlock(i + 5, j + 8, k + 6, 0);
		world.setBlock(i + 5, j + 8, k + 7, 0);
		world.setBlock(i + 5, j + 8, k + 8, 0);
		world.setBlock(i + 5, j + 8, k + 9, 0);
		world.setBlock(i + 5, j + 8, k + 10, 0);
		world.setBlock(i + 5, j + 8, k + 11, Block.stone.blockID);
		world.setBlock(i + 5, j + 9, k + 0, Block.web.blockID);
		world.setBlock(i + 5, j + 9, k + 1, Block.stone.blockID);
		world.setBlock(i + 5, j + 9, k + 2, 0);
		world.setBlock(i + 5, j + 9, k + 3, 0);
		world.setBlock(i + 5, j + 9, k + 4, 0);
		world.setBlock(i + 5, j + 9, k + 5, 0);
		world.setBlock(i + 5, j + 9, k + 6, 0);
		world.setBlock(i + 5, j + 9, k + 7, 0);
		world.setBlock(i + 5, j + 9, k + 8, 0);
		world.setBlock(i + 5, j + 9, k + 9, 0);
		world.setBlock(i + 5, j + 9, k + 10, 0);
		world.setBlock(i + 5, j + 9, k + 11, Block.stone.blockID);
		world.setBlock(i + 5, j + 9, k + 12, Block.web.blockID);
		world.setBlock(i + 5, j + 10, k + 0, 0);
		world.setBlock(i + 5, j + 10, k + 1, Block.stone.blockID);
		world.setBlock(i + 5, j + 10, k + 2, 0);
		world.setBlock(i + 5, j + 10, k + 3, 0);
		world.setBlock(i + 5, j + 10, k + 4, 0);
		world.setBlock(i + 5, j + 10, k + 5, 0);
		world.setBlock(i + 5, j + 10, k + 6, 0);
		world.setBlock(i + 5, j + 10, k + 7, 0);
		world.setBlock(i + 5, j + 10, k + 8, 0);
		world.setBlock(i + 5, j + 10, k + 9, 0);
		world.setBlock(i + 5, j + 10, k + 10, 0);
		world.setBlock(i + 5, j + 10, k + 11, Block.stone.blockID);
		world.setBlock(i + 5, j + 10, k + 12, 0);
		world.setBlock(i + 5, j + 11, k + 0, 0);
		world.setBlock(i + 5, j + 11, k + 1, Block.stone.blockID);
		world.setBlock(i + 5, j + 11, k + 2, Block.stoneBrick.blockID);
		world.setBlock(i + 5, j + 11, k + 3, Block.stoneBrick.blockID);
		world.setBlockMetadataWithNotify(i + 5, j + 11, k + 4, Block.stoneBrick.blockID, 1);
		world.setBlock(i + 5, j + 11, k + 5, Block.stoneBrick.blockID);
		world.setBlock(i + 5, j + 11, k + 6, Block.stoneBrick.blockID);
		world.setBlock(i + 5, j + 11, k + 7, Block.stoneBrick.blockID);
		world.setBlock(i + 5, j + 11, k + 8, Block.stoneBrick.blockID);
		world.setBlock(i + 5, j + 11, k + 9, Block.stoneBrick.blockID);
		world.setBlock(i + 5, j + 11, k + 10, Block.stoneBrick.blockID);
		world.setBlock(i + 5, j + 11, k + 11, Block.stone.blockID);
		world.setBlock(i + 5, j + 11, k + 12, 0);
		world.setBlock(i + 5, j + 12, k + 0, 0);
		world.setBlock(i + 5, j + 12, k + 1, Block.stoneBrick.blockID);
		world.setBlock(i + 5, j + 12, k + 2, 0);
		world.setBlock(i + 5, j + 12, k + 3, Block.web.blockID);
		world.setBlock(i + 5, j + 12, k + 4, 0);
		world.setBlock(i + 5, j + 12, k + 5, 0);
		world.setBlock(i + 5, j + 12, k + 6, 0);
		world.setBlock(i + 5, j + 12, k + 7, Block.web.blockID);
		world.setBlock(i + 5, j + 12, k + 8, 0);
		world.setBlock(i + 5, j + 12, k + 9, 0);
		world.setBlock(i + 5, j + 12, k + 10, Block.web.blockID);
		world.setBlock(i + 5, j + 12, k + 11, Block.stoneBrick.blockID);
		world.setBlock(i + 5, j + 13, k + 0, 0);
		world.setBlock(i + 5, j + 13, k + 1, Block.stoneBrick.blockID);
		world.setBlock(i + 5, j + 13, k + 2, 0);
		world.setBlock(i + 5, j + 13, k + 3, 0);
		world.setBlock(i + 5, j + 13, k + 4, 0);
		world.setBlock(i + 5, j + 13, k + 5, 0);
		world.setBlock(i + 5, j + 13, k + 6, 0);
		world.setBlock(i + 5, j + 13, k + 7, 0);
		world.setBlock(i + 5, j + 13, k + 8, 0);
		world.setBlock(i + 5, j + 13, k + 9, 0);
		world.setBlock(i + 5, j + 13, k + 10, 0);
		world.setBlockMetadataWithNotify(i + 5, j + 13, k + 11, Block.stoneBrick.blockID, 2);
		world.setBlock(i + 5, j + 13, k + 12, 0);
		world.setBlock(i + 5, j + 14, k + 1, Block.stoneBrick.blockID);
		world.setBlock(i + 5, j + 14, k + 2, 0);
		world.setBlock(i + 5, j + 14, k + 3, 0);
		world.setBlock(i + 5, j + 14, k + 4, 0);
		world.setBlock(i + 5, j + 14, k + 5, 0);
		world.setBlock(i + 5, j + 14, k + 6, 0);
		world.setBlock(i + 5, j + 14, k + 7, 0);
		world.setBlock(i + 5, j + 14, k + 8, 0);
		world.setBlock(i + 5, j + 14, k + 9, 0);
		world.setBlock(i + 5, j + 14, k + 10, Block.web.blockID);
		world.setBlock(i + 5, j + 14, k + 11, Block.stoneBrick.blockID);
		world.setBlock(i + 5, j + 14, k + 12, 0);
		world.setBlock(i + 5, j + 15, k + 0, 0);
		world.setBlock(i + 5, j + 15, k + 1, 0);
		world.setBlock(i + 5, j + 15, k + 2, Block.stoneBrick.blockID);
		world.setBlock(i + 5, j + 15, k + 3, 0);
		world.setBlock(i + 5, j + 15, k + 4, 0);
		world.setBlock(i + 5, j + 15, k + 5, 0);
		world.setBlock(i + 5, j + 15, k + 6, 0);
		world.setBlock(i + 5, j + 15, k + 7, 0);
		world.setBlock(i + 5, j + 15, k + 8, 0);
		world.setBlock(i + 5, j + 15, k + 9, 0);
		world.setBlock(i + 5, j + 15, k + 10, Block.stoneBrick.blockID);
		world.setBlock(i + 5, j + 15, k + 11, 0);
		world.setBlock(i + 5, j + 15, k + 12, 0);
		world.setBlock(i + 5, j + 16, k + 0, 0);
		world.setBlock(i + 5, j + 16, k + 1, 0);
		world.setBlock(i + 5, j + 16, k + 2, 0);
		world.setBlock(i + 5, j + 16, k + 3, Block.stoneBrick.blockID);
		world.setBlock(i + 5, j + 16, k + 4, 0);
		world.setBlock(i + 5, j + 16, k + 5, 0);
		world.setBlock(i + 5, j + 16, k + 6, 0);
		world.setBlock(i + 5, j + 16, k + 7, 0);
		world.setBlock(i + 5, j + 16, k + 8, 0);
		world.setBlock(i + 5, j + 16, k + 9, Block.stoneBrick.blockID);
		world.setBlock(i + 5, j + 16, k + 10, 0);
		world.setBlock(i + 5, j + 16, k + 11, 0);
		world.setBlock(i + 5, j + 16, k + 12, 0);
		world.setBlock(i + 5, j + 17, k + 0, 0);
		world.setBlock(i + 5, j + 17, k + 1, 0);
		world.setBlock(i + 5, j + 17, k + 2, 0);
		world.setBlock(i + 5, j + 17, k + 3, 0);
		world.setBlock(i + 5, j + 17, k + 4, Block.stoneBrick.blockID);
		world.setBlock(i + 5, j + 17, k + 5, 0);
		world.setBlock(i + 5, j + 17, k + 6, 0);
		world.setBlock(i + 5, j + 17, k + 7, 0);
		world.setBlock(i + 5, j + 17, k + 8, Block.stoneBrick.blockID);
		world.setBlock(i + 5, j + 17, k + 10, 0);
		world.setBlock(i + 5, j + 17, k + 11, 0);
		world.setBlock(i + 5, j + 17, k + 12, 0);
		world.setBlock(i + 5, j + 18, k + 0, 0);
		world.setBlock(i + 5, j + 18, k + 1, 0);
		world.setBlock(i + 5, j + 18, k + 2, 0);
		world.setBlock(i + 5, j + 18, k + 3, 0);
		world.setBlock(i + 5, j + 18, k + 5, Block.stoneBrick.blockID);
		world.setBlock(i + 5, j + 18, k + 6, 0);
		world.setBlock(i + 5, j + 18, k + 7, Block.stoneBrick.blockID);
		world.setBlock(i + 5, j + 18, k + 8, 0);
		world.setBlock(i + 5, j + 18, k + 9, 0);
		world.setBlock(i + 5, j + 18, k + 10, 0);
		world.setBlock(i + 5, j + 18, k + 11, 0);
		world.setBlock(i + 5, j + 18, k + 12, 0);
		world.setBlock(i + 5, j + 19, k + 0, 0);
		world.setBlock(i + 5, j + 19, k + 1, 0);
		world.setBlock(i + 5, j + 19, k + 2, 0);
		world.setBlock(i + 5, j + 19, k + 3, 0);
		world.setBlock(i + 5, j + 19, k + 4, 0);
		world.setBlock(i + 5, j + 19, k + 5, 0);
		world.setBlock(i + 5, j + 19, k + 6, Block.stoneBrick.blockID);
		world.setBlock(i + 5, j + 19, k + 7, 0);
		world.setBlock(i + 5, j + 19, k + 8, 0);
		world.setBlock(i + 5, j + 19, k + 9, 0);
		world.setBlock(i + 5, j + 19, k + 10, 0);
		world.setBlock(i + 5, j + 19, k + 11, 0);
		world.setBlock(i + 5, j + 19, k + 12, 0);
		world.setBlock(i + 6, j + 0, k + 0, 0);
		world.setBlock(i + 6, j + 0, k + 1, Block.stone.blockID);
		world.setBlock(i + 6, j + 0, k + 2, Block.cloth.blockID);
		world.setBlock(i + 6, j + 0, k + 3, Block.cloth.blockID);
		world.setBlock(i + 6, j + 0, k + 4, Block.cloth.blockID);
		world.setBlock(i + 6, j + 0, k + 5, Block.cloth.blockID);
		world.setBlockMetadataWithNotify(i + 6, j + 0, k + 6, Block.cloth.blockID, 14);
		world.setBlock(i + 6, j + 0, k + 7, Block.cloth.blockID);
		world.setBlock(i + 6, j + 0, k + 8, Block.cloth.blockID);
		world.setBlock(i + 6, j + 0, k + 9, Block.cloth.blockID);
		world.setBlock(i + 6, j + 0, k + 10, Block.cloth.blockID);
		world.setBlock(i + 6, j + 0, k + 11, Block.stone.blockID);
		world.setBlock(i + 6, j + 0, k + 12, 0);
		world.setBlock(i + 6, j + 1, k + 0, 0);
		world.setBlock(i + 6, j + 1, k + 1, Block.stone.blockID);
		world.setBlock(i + 6, j + 1, k + 2, Block.glowStone.blockID);
		world.setBlock(i + 6, j + 1, k + 3, Block.glowStone.blockID);
		world.setBlock(i + 6, j + 1, k + 4, 0);
		world.setBlock(i + 6, j + 1, k + 5, 0);
		world.setBlock(i + 6, j + 1, k + 6, Block.web.blockID);
		world.setBlock(i + 6, j + 1, k + 7, 0);
		world.setBlock(i + 6, j + 1, k + 8, 0);
		world.setBlock(i + 6, j + 1, k + 9, Block.glowStone.blockID);
		world.setBlock(i + 6, j + 1, k + 10, Block.glowStone.blockID);
		world.setBlock(i + 6, j + 1, k + 11, Block.stone.blockID);
		world.setBlock(i + 6, j + 1, k + 12, 0);
		world.setBlock(i + 6, j + 2, k + 1, Block.stone.blockID);
		world.setBlock(i + 6, j + 2, k + 2, Block.glowStone.blockID);
		world.setBlock(i + 6, j + 2, k + 3, Block.web.blockID);
		world.setBlock(i + 6, j + 2, k + 4, 0);
		world.setBlock(i + 6, j + 2, k + 5, 0);
		world.setBlock(i + 6, j + 2, k + 6, 0);
		world.setBlock(i + 6, j + 2, k + 7, 0);
		world.setBlock(i + 6, j + 2, k + 8, Block.web.blockID);
		world.setBlock(i + 6, j + 2, k + 9, Block.glowStone.blockID);
		world.setBlock(i + 6, j + 2, k + 10, Block.glowStone.blockID);
		world.setBlock(i + 6, j + 2, k + 11, Block.stone.blockID);
		world.setBlock(i + 6, j + 2, k + 12, Block.web.blockID);
		world.setBlock(i + 6, j + 3, k + 0, 0);
		world.setBlock(i + 6, j + 3, k + 1, Block.stone.blockID);
		world.setBlock(i + 6, j + 3, k + 2, Block.stoneBrick.blockID);
		world.setBlock(i + 6, j + 3, k + 3, Block.stoneBrick.blockID);
		world.setBlock(i + 6, j + 3, k + 5, 0);
		world.setBlock(i + 6, j + 3, k + 6, 0);
		world.setBlock(i + 6, j + 3, k + 7, 0);
		world.setBlock(i + 6, j + 3, k + 9, Block.stoneBrick.blockID);
		world.setBlock(i + 6, j + 3, k + 10, Block.stoneBrick.blockID);
		world.setBlock(i + 6, j + 3, k + 11, Block.stone.blockID);
		world.setBlock(i + 6, j + 3, k + 12, 0);

		generate2(world, rand, i, j, k);
		return true;
	}

	public boolean generate2(World world, Random rand, int i, int j, int k)
	{
		world.setBlock(i + 6, j + 4, k + 0, 0);
		world.setBlock(i + 6, j + 4, k + 1, Block.stone.blockID);
		world.setBlock(i + 6, j + 4, k + 2, Block.web.blockID);
		world.setBlock(i + 6, j + 4, k + 3, 0);
		world.setBlock(i + 6, j + 4, k + 4, 0);
		world.setBlock(i + 6, j + 4, k + 5, 0);
		world.setBlock(i + 6, j + 4, k + 6, 0);
		world.setBlock(i + 6, j + 4, k + 7, 0);
		world.setBlock(i + 6, j + 4, k + 8, 0);
		world.setBlock(i + 6, j + 4, k + 10, 0);
		world.setBlock(i + 6, j + 4, k + 11, Block.stone.blockID);
		world.setBlock(i + 6, j + 4, k + 12, 0);
		world.setBlock(i + 6, j + 5, k + 0, 0);
		world.setBlock(i + 6, j + 5, k + 1, Block.stoneBrick.blockID);
		world.setBlock(i + 6, j + 5, k + 3, 0);
		world.setBlock(i + 6, j + 5, k + 4, Block.web.blockID);
		world.setBlock(i + 6, j + 5, k + 5, 0);
		world.setBlock(i + 6, j + 5, k + 6, 0);
		world.setBlock(i + 6, j + 5, k + 7, 0);
		world.setBlock(i + 6, j + 5, k + 9, 0);
		world.setBlock(i + 6, j + 5, k + 10, 0);
		world.setBlock(i + 6, j + 5, k + 11, Block.stoneBrick.blockID);
		world.setBlock(i + 6, j + 5, k + 12, Block.web.blockID);
		world.setBlock(i + 6, j + 6, k + 1, Block.stone.blockID);
		world.setBlock(i + 6, j + 6, k + 3, 0);
		world.setBlock(i + 6, j + 6, k + 4, 0);
		world.setBlock(i + 6, j + 6, k + 5, 0);
		world.setBlock(i + 6, j + 6, k + 7, 0);
		world.setBlock(i + 6, j + 6, k + 8, 0);
		world.setBlock(i + 6, j + 6, k + 9, 0);
		world.setBlock(i + 6, j + 6, k + 10, 0);
		world.setBlock(i + 6, j + 6, k + 11, Block.stone.blockID);
		world.setBlock(i + 6, j + 7, k + 1, Block.stone.blockID);
		world.setBlock(i + 6, j + 7, k + 3, 0);
		world.setBlock(i + 6, j + 7, k + 4, Block.web.blockID);
		world.setBlock(i + 6, j + 7, k + 5, Block.stoneBrick.blockID);
		world.setBlock(i + 6, j + 7, k + 6, Block.stoneBrick.blockID);
		world.setBlock(i + 6, j + 7, k + 7, Block.stoneBrick.blockID);
		world.setBlock(i + 6, j + 7, k + 8, 0);
		world.setBlock(i + 6, j + 7, k + 9, 0);
		world.setBlock(i + 6, j + 7, k + 10, 0);
		world.setBlock(i + 6, j + 7, k + 11, Block.stone.blockID);
		world.setBlock(i + 6, j + 7, k + 12, 0);
		world.setBlock(i + 6, j + 8, k + 1, Block.stone.blockID);
		world.setBlock(i + 6, j + 8, k + 2, Block.web.blockID);
		world.setBlock(i + 6, j + 8, k + 3, 0);
		world.setBlock(i + 6, j + 8, k + 4, 0);
		world.setBlock(i + 6, j + 8, k + 6, Block.web.blockID);
		world.setBlock(i + 6, j + 8, k + 7, Block.web.blockID);
		world.setBlock(i + 6, j + 8, k + 8, 0);
		world.setBlock(i + 6, j + 8, k + 9, 0);
		world.setBlock(i + 6, j + 8, k + 10, 0);
		world.setBlock(i + 6, j + 8, k + 11, Block.stone.blockID);
		world.setBlock(i + 6, j + 8, k + 12, 0);
		world.setBlock(i + 6, j + 9, k + 1, Block.stone.blockID);
		world.setBlock(i + 6, j + 9, k + 2, Block.web.blockID);
		world.setBlock(i + 6, j + 9, k + 3, 0);
		world.setBlock(i + 6, j + 9, k + 4, 0);
		world.setBlock(i + 6, j + 9, k + 6, 0);
		world.setBlock(i + 6, j + 9, k + 7, 0);
		world.setBlock(i + 6, j + 9, k + 8, 0);
		world.setBlock(i + 6, j + 9, k + 9, 0);
		world.setBlock(i + 6, j + 9, k + 10, Block.web.blockID);
		world.setBlock(i + 6, j + 9, k + 11, Block.stone.blockID);
		world.setBlock(i + 6, j + 9, k + 12, 0);
		world.setBlock(i + 6, j + 10, k + 0, 0);
		world.setBlock(i + 6, j + 10, k + 1, Block.stone.blockID);
		world.setBlock(i + 6, j + 10, k + 2, 0);
		world.setBlock(i + 6, j + 10, k + 3, 0);
		world.setBlock(i + 6, j + 10, k + 4, 0);
		world.setBlock(i + 6, j + 10, k + 6, 0);
		world.setBlock(i + 6, j + 10, k + 7, 0);
		world.setBlock(i + 6, j + 10, k + 8, 0);
		world.setBlock(i + 6, j + 10, k + 9, 0);
		world.setBlock(i + 6, j + 10, k + 10, 0);
		world.setBlock(i + 6, j + 10, k + 11, Block.stone.blockID);
		world.setBlock(i + 6, j + 10, k + 12, 0);
		world.setBlock(i + 6, j + 11, k + 0, 0);
		world.setBlock(i + 6, j + 11, k + 1, Block.stone.blockID);
		world.setBlockMetadataWithNotify(i + 6, j + 11, k + 2, Block.stoneBrick.blockID, 2);
		world.setBlockMetadataWithNotify(i + 6, j + 11, k + 3, Block.stoneBrick.blockID, 1);
		world.setBlock(i + 6, j + 11, k + 4, Block.stoneBrick.blockID);
		world.setBlock(i + 6, j + 11, k + 6, 0);
		world.setBlock(i + 6, j + 11, k + 7, 0);
		world.setBlock(i + 6, j + 11, k + 8, Block.stoneBrick.blockID);
		world.setBlock(i + 6, j + 11, k + 9, Block.stoneBrick.blockID);
		world.setBlock(i + 6, j + 11, k + 10, Block.stoneBrick.blockID);
		world.setBlock(i + 6, j + 11, k + 11, Block.stone.blockID);
		world.setBlock(i + 6, j + 11, k + 12, 0);
		world.setBlock(i + 6, j + 12, k + 0, 0);
		world.setBlock(i + 6, j + 12, k + 1, Block.stoneBrick.blockID);
		world.setBlock(i + 6, j + 12, k + 2, Block.web.blockID);
		world.setBlock(i + 6, j + 12, k + 3, 0);
		world.setBlock(i + 6, j + 12, k + 4, 0);
		world.setBlock(i + 6, j + 12, k + 5, 0);
		world.setBlock(i + 6, j + 12, k + 6, 0);
		world.setBlock(i + 6, j + 12, k + 7, 0);
		world.setBlock(i + 6, j + 12, k + 8, 0);
		world.setBlock(i + 6, j + 12, k + 9, 0);
		world.setBlock(i + 6, j + 12, k + 10, 0);
		world.setBlock(i + 6, j + 12, k + 11, Block.stoneBrick.blockID);
		world.setBlock(i + 6, j + 12, k + 12, 0);
		world.setBlock(i + 6, j + 13, k + 0, 0);
		world.setBlock(i + 6, j + 13, k + 1, Block.stoneBrick.blockID);
		world.setBlock(i + 6, j + 13, k + 2, 0);
		world.setBlock(i + 6, j + 13, k + 3, 0);
		world.setBlock(i + 6, j + 13, k + 4, 0);
		world.setBlock(i + 6, j + 13, k + 5, 0);
		world.setBlock(i + 6, j + 13, k + 6, 0);
		world.setBlock(i + 6, j + 13, k + 7, 0);
		world.setBlock(i + 6, j + 13, k + 8, 0);
		world.setBlock(i + 6, j + 13, k + 9, 0);
		world.setBlock(i + 6, j + 13, k + 10, 0);
		world.setBlock(i + 6, j + 13, k + 11, Block.stoneBrick.blockID);
		world.setBlock(i + 6, j + 13, k + 12, 0);
		world.setBlock(i + 6, j + 14, k + 1, Block.stoneBrick.blockID);
		world.setBlock(i + 6, j + 14, k + 2, 0);
		world.setBlock(i + 6, j + 14, k + 3, 0);
		world.setBlock(i + 6, j + 14, k + 4, 0);
		world.setBlock(i + 6, j + 14, k + 5, 0);
		world.setBlock(i + 6, j + 14, k + 6, 0);
		world.setBlock(i + 6, j + 14, k + 7, 0);
		world.setBlock(i + 6, j + 14, k + 8, 0);
		world.setBlock(i + 6, j + 14, k + 9, Block.web.blockID);
		world.setBlock(i + 6, j + 14, k + 10, 0);
		world.setBlock(i + 6, j + 14, k + 11, Block.stoneBrick.blockID);
		world.setBlock(i + 6, j + 15, k + 0, 0);
		world.setBlock(i + 6, j + 15, k + 1, 0);
		world.setBlock(i + 6, j + 15, k + 2, Block.stoneBrick.blockID);
		world.setBlockMetadataWithNotify(i + 6, j + 15, k + 3, Block.planks.blockID, 1);
		world.setBlockMetadataWithNotify(i + 6, j + 15, k + 4, Block.planks.blockID, 1);
		world.setBlockMetadataWithNotify(i + 6, j + 15, k + 5, Block.planks.blockID, 1);
		world.setBlockMetadataWithNotify(i + 6, j + 15, k + 6, Block.planks.blockID, 1);
		world.setBlockMetadataWithNotify(i + 6, j + 15, k + 7, Block.planks.blockID, 1);
		world.setBlockMetadataWithNotify(i + 6, j + 15, k + 8, Block.planks.blockID, 1);
		world.setBlockMetadataWithNotify(i + 6, j + 15, k + 9, Block.planks.blockID, 1);
		world.setBlock(i + 6, j + 15, k + 10, Block.stoneBrick.blockID);
		world.setBlock(i + 6, j + 15, k + 12, 0);
		world.setBlock(i + 6, j + 16, k + 0, 0);
		world.setBlock(i + 6, j + 16, k + 1, 0);
		world.setBlock(i + 6, j + 16, k + 2, 0);
		world.setBlock(i + 6, j + 16, k + 3, Block.stoneBrick.blockID);
		world.setBlock(i + 6, j + 16, k + 4, 0);
		world.setBlock(i + 6, j + 16, k + 5, 0);
		world.setBlockMetadataWithNotify(i + 6, j + 16, k + 6, Block.planks.blockID, 1);
		world.setBlock(i + 6, j + 16, k + 7, 0);
		world.setBlock(i + 6, j + 16, k + 8, 0);
		world.setBlock(i + 6, j + 16, k + 9, Block.stoneBrick.blockID);
		world.setBlock(i + 6, j + 16, k + 11, 0);
		world.setBlock(i + 6, j + 16, k + 12, 0);
		world.setBlock(i + 6, j + 17, k + 0, 0);
		world.setBlock(i + 6, j + 17, k + 1, 0);
		world.setBlock(i + 6, j + 17, k + 2, 0);
		world.setBlock(i + 6, j + 17, k + 4, Block.stoneBrick.blockID);
		world.setBlock(i + 6, j + 17, k + 5, Block.web.blockID);
		world.setBlockMetadataWithNotify(i + 6, j + 17, k + 6, Block.planks.blockID, 1);
		world.setBlock(i + 6, j + 17, k + 7, 0);
		world.setBlock(i + 6, j + 17, k + 8, Block.stoneBrick.blockID);
		world.setBlock(i + 6, j + 17, k + 9, 0);
		world.setBlock(i + 6, j + 17, k + 10, 0);
		world.setBlock(i + 6, j + 17, k + 11, 0);
		world.setBlock(i + 6, j + 17, k + 12, 0);
		world.setBlock(i + 6, j + 18, k + 0, 0);
		world.setBlock(i + 6, j + 18, k + 1, 0);
		world.setBlock(i + 6, j + 18, k + 2, Block.web.blockID);
		world.setBlock(i + 6, j + 18, k + 3, Block.web.blockID);
		world.setBlock(i + 6, j + 18, k + 4, Block.web.blockID);
		world.setBlock(i + 6, j + 18, k + 5, Block.stoneBrick.blockID);
		world.setBlockMetadataWithNotify(i + 6, j + 18, k + 6, Block.planks.blockID, 1);
		world.setBlock(i + 6, j + 18, k + 7, Block.stoneBrick.blockID);
		world.setBlock(i + 6, j + 18, k + 9, 0);
		world.setBlock(i + 6, j + 18, k + 10, 0);
		world.setBlock(i + 6, j + 18, k + 11, 0);
		world.setBlock(i + 6, j + 18, k + 12, 0);
		world.setBlock(i + 6, j + 19, k + 0, 0);
		world.setBlock(i + 6, j + 19, k + 1, 0);
		world.setBlock(i + 6, j + 19, k + 2, 0);
		world.setBlock(i + 6, j + 19, k + 3, 0);
		world.setBlock(i + 6, j + 19, k + 4, 0);
		world.setBlock(i + 6, j + 19, k + 5, 0);
		world.setBlock(i + 6, j + 19, k + 6, Block.stoneBrick.blockID);
		world.setBlock(i + 6, j + 19, k + 7, 0);
		world.setBlock(i + 6, j + 19, k + 8, 0);
		world.setBlock(i + 6, j + 19, k + 9, 0);
		world.setBlock(i + 6, j + 19, k + 10, 0);
		world.setBlock(i + 6, j + 19, k + 11, 0);
		world.setBlock(i + 6, j + 19, k + 12, 0);
		world.setBlock(i + 7, j + 0, k + 0, 0);
		world.setBlock(i + 7, j + 0, k + 1, Block.stone.blockID);
		world.setBlock(i + 7, j + 0, k + 2, Block.cloth.blockID);
		world.setBlock(i + 7, j + 0, k + 3, Block.cloth.blockID);
		world.setBlock(i + 7, j + 0, k + 4, Block.cloth.blockID);
		world.setBlock(i + 7, j + 0, k + 5, Block.cloth.blockID);
		world.setBlockMetadataWithNotify(i + 7, j + 0, k + 6, Block.cloth.blockID, 14);
		world.setBlock(i + 7, j + 0, k + 7, Block.cloth.blockID);
		world.setBlock(i + 7, j + 0, k + 8, Block.cloth.blockID);
		world.setBlock(i + 7, j + 0, k + 9, Block.cloth.blockID);
		world.setBlock(i + 7, j + 0, k + 10, Block.cloth.blockID);
		world.setBlock(i + 7, j + 0, k + 11, Block.stone.blockID);
		world.setBlock(i + 7, j + 0, k + 12, 0);
		world.setBlock(i + 7, j + 1, k + 0, 0);
		world.setBlock(i + 7, j + 1, k + 1, Block.stone.blockID);
		world.setBlock(i + 7, j + 1, k + 2, Block.glowStone.blockID);
		world.setBlock(i + 7, j + 1, k + 3, Block.glowStone.blockID);
		world.setBlock(i + 7, j + 1, k + 4, 0);
		world.setBlock(i + 7, j + 1, k + 5, Block.web.blockID);
		world.setBlock(i + 7, j + 1, k + 6, 0);
		world.setBlock(i + 7, j + 1, k + 7, 0);
		world.setBlock(i + 7, j + 1, k + 8, 0);
		world.setBlock(i + 7, j + 1, k + 9, Block.web.blockID);
		world.setBlock(i + 7, j + 1, k + 10, Block.glowStone.blockID);
		world.setBlock(i + 7, j + 1, k + 11, Block.stone.blockID);
		world.setBlock(i + 7, j + 1, k + 12, 0);
		world.setBlock(i + 7, j + 2, k + 1, Block.stone.blockID);
		world.setBlock(i + 7, j + 2, k + 2, Block.stoneBrick.blockID);
		world.setBlock(i + 7, j + 2, k + 3, Block.stoneBrick.blockID);
		world.setBlock(i + 7, j + 2, k + 4, 0);
		world.setBlock(i + 7, j + 2, k + 5, 0);
		world.setBlock(i + 7, j + 2, k + 6, 0);
		world.setBlock(i + 7, j + 2, k + 7, 0);
		world.setBlock(i + 7, j + 2, k + 8, 0);
		world.setBlock(i + 7, j + 2, k + 9, Block.stoneBrick.blockID);
		world.setBlock(i + 7, j + 2, k + 10, Block.stoneBrick.blockID);
		world.setBlock(i + 7, j + 2, k + 11, Block.stone.blockID);
		world.setBlock(i + 7, j + 2, k + 12, 0);
		world.setBlock(i + 7, j + 3, k + 0, 0);
		world.setBlock(i + 7, j + 3, k + 1, Block.stone.blockID);
		world.setBlock(i + 7, j + 3, k + 2, Block.web.blockID);
		world.setBlock(i + 7, j + 3, k + 4, 0);
		world.setBlock(i + 7, j + 3, k + 5, 0);
		world.setBlock(i + 7, j + 3, k + 6, 0);
		world.setBlock(i + 7, j + 3, k + 7, 0);
		world.setBlock(i + 7, j + 3, k + 8, 0);
		world.setBlock(i + 7, j + 3, k + 10, Block.web.blockID);
		world.setBlock(i + 7, j + 3, k + 11, Block.stone.blockID);
		world.setBlock(i + 7, j + 3, k + 12, 0);
		world.setBlock(i + 7, j + 4, k + 0, 0);
		world.setBlock(i + 7, j + 4, k + 1, Block.stone.blockID);
		world.setBlock(i + 7, j + 4, k + 2, 0);
		world.setBlock(i + 7, j + 4, k + 3, 0);
		world.setBlock(i + 7, j + 4, k + 4, 0);
		world.setBlock(i + 7, j + 4, k + 5, 0);
		world.setBlock(i + 7, j + 4, k + 6, 0);
		world.setBlock(i + 7, j + 4, k + 7, 0);
		world.setBlock(i + 7, j + 4, k + 8, 0);
		world.setBlock(i + 7, j + 4, k + 9, 0);
		world.setBlock(i + 7, j + 4, k + 11, Block.stone.blockID);
		world.setBlock(i + 7, j + 4, k + 12, 0);
		world.setBlock(i + 7, j + 5, k + 0, 0);
		world.setBlock(i + 7, j + 5, k + 1, Block.stoneBrick.blockID);
		world.setBlock(i + 7, j + 5, k + 2, 0);
		world.setBlock(i + 7, j + 5, k + 3, 0);
		world.setBlock(i + 7, j + 5, k + 4, Block.web.blockID);
		world.setBlock(i + 7, j + 5, k + 5, Block.web.blockID);
		world.setBlock(i + 7, j + 5, k + 6, 0);
		world.setBlock(i + 7, j + 5, k + 7, 0);
		world.setBlock(i + 7, j + 5, k + 8, 0);
		world.setBlock(i + 7, j + 5, k + 9, 0);
		world.setBlock(i + 7, j + 5, k + 11, Block.stoneBrick.blockID);
		world.setBlock(i + 7, j + 5, k + 12, Block.web.blockID);
		world.setBlock(i + 7, j + 6, k + 0, 0);
		world.setBlock(i + 7, j + 6, k + 1, Block.stone.blockID);
		world.setBlock(i + 7, j + 6, k + 2, 0);
		world.setBlock(i + 7, j + 6, k + 3, 0);
		world.setBlock(i + 7, j + 6, k + 4, 0);
		world.setBlock(i + 7, j + 6, k + 5, 0);
		world.setBlock(i + 7, j + 6, k + 7, 0);
		world.setBlock(i + 7, j + 6, k + 8, 0);
		world.setBlock(i + 7, j + 6, k + 9, 0);
		world.setBlock(i + 7, j + 6, k + 11, Block.stone.blockID);
		world.setBlock(i + 7, j + 6, k + 12, 0);
		world.setBlock(i + 7, j + 7, k + 0, 0);
		world.setBlock(i + 7, j + 7, k + 1, Block.stone.blockID);
		world.setBlock(i + 7, j + 7, k + 2, 0);
		world.setBlock(i + 7, j + 7, k + 3, 0);
		world.setBlock(i + 7, j + 7, k + 4, 0);
		world.setBlock(i + 7, j + 7, k + 5, 0);
		world.setBlock(i + 7, j + 7, k + 7, 0);
		world.setBlock(i + 7, j + 7, k + 9, 0);
		world.setBlock(i + 7, j + 7, k + 11, Block.stone.blockID);
		world.setBlock(i + 7, j + 8, k + 0, 0);
		world.setBlock(i + 7, j + 8, k + 1, Block.stone.blockID);
		world.setBlock(i + 7, j + 8, k + 2, 0);
		world.setBlock(i + 7, j + 8, k + 3, 0);
		world.setBlock(i + 7, j + 8, k + 4, 0);
		world.setBlock(i + 7, j + 8, k + 5, Block.stoneBrick.blockID);
		world.setBlock(i + 7, j + 8, k + 6, Block.stoneBrick.blockID);
		world.setBlock(i + 7, j + 8, k + 7, Block.stoneBrick.blockID);
		world.setBlock(i + 7, j + 8, k + 9, 0);
		world.setBlock(i + 7, j + 8, k + 11, Block.stone.blockID);
		world.setBlock(i + 7, j + 8, k + 12, 0);
		world.setBlock(i + 7, j + 9, k + 0, Block.web.blockID);
		world.setBlock(i + 7, j + 9, k + 1, Block.stone.blockID);
		world.setBlock(i + 7, j + 9, k + 2, 0);
		world.setBlock(i + 7, j + 9, k + 3, 0);
		world.setBlock(i + 7, j + 9, k + 4, 0);
		world.setBlock(i + 7, j + 9, k + 5, 0);
		world.setBlock(i + 7, j + 9, k + 6, 0);
		world.setBlock(i + 7, j + 9, k + 7, Block.web.blockID);
		world.setBlock(i + 7, j + 9, k + 8, 0);
		world.setBlock(i + 7, j + 9, k + 9, 0);
		world.setBlock(i + 7, j + 9, k + 10, Block.web.blockID);
		world.setBlock(i + 7, j + 9, k + 11, Block.stone.blockID);
		world.setBlock(i + 7, j + 10, k + 0, 0);
		world.setBlock(i + 7, j + 10, k + 1, Block.stone.blockID);
		world.setBlock(i + 7, j + 10, k + 2, 0);
		world.setBlock(i + 7, j + 10, k + 3, 0);
		world.setBlock(i + 7, j + 10, k + 4, 0);
		world.setBlock(i + 7, j + 10, k + 6, 0);
		world.setBlock(i + 7, j + 10, k + 7, 0);
		world.setBlock(i + 7, j + 10, k + 8, 0);
		world.setBlock(i + 7, j + 10, k + 9, 0);
		world.setBlock(i + 7, j + 10, k + 11, Block.stone.blockID);
		world.setBlock(i + 7, j + 10, k + 12, 0);
		world.setBlock(i + 7, j + 11, k + 0, 0);
		world.setBlock(i + 7, j + 11, k + 1, Block.stone.blockID);
		world.setBlock(i + 7, j + 11, k + 2, Block.stoneBrick.blockID);
		world.setBlock(i + 7, j + 11, k + 3, Block.stoneBrick.blockID);
		world.setBlock(i + 7, j + 11, k + 4, Block.stoneBrick.blockID);
		world.setBlock(i + 7, j + 11, k + 6, 0);
		world.setBlock(i + 7, j + 11, k + 7, Block.web.blockID);
		world.setBlock(i + 7, j + 11, k + 8, Block.stoneBrick.blockID);
		world.setBlock(i + 7, j + 11, k + 9, Block.stoneBrick.blockID);
		world.setBlock(i + 7, j + 11, k + 10, Block.stoneBrick.blockID);
		world.setBlock(i + 7, j + 11, k + 11, Block.stone.blockID);
		world.setBlock(i + 7, j + 12, k + 0, 0);
		world.setBlockMetadataWithNotify(i + 7, j + 12, k + 1, Block.stoneBrick.blockID, 1);
		world.setBlock(i + 7, j + 12, k + 2, 0);
		world.setBlock(i + 7, j + 12, k + 3, 0);
		world.setBlock(i + 7, j + 12, k + 4, 0);
		world.setBlock(i + 7, j + 12, k + 5, 0);
		world.setBlock(i + 7, j + 12, k + 6, 0);
		world.setBlock(i + 7, j + 12, k + 7, 0);
		world.setBlock(i + 7, j + 12, k + 8, Block.web.blockID);
		world.setBlock(i + 7, j + 12, k + 9, 0);
		world.setBlock(i + 7, j + 12, k + 10, 0);
		world.setBlockMetadataWithNotify(i + 7, j + 12, k + 11, Block.stoneBrick.blockID, 2);
		world.setBlock(i + 7, j + 13, k + 0, 0);
		world.setBlock(i + 7, j + 13, k + 1, Block.stoneBrick.blockID);
		world.setBlock(i + 7, j + 13, k + 2, 0);
		world.setBlock(i + 7, j + 13, k + 3, 0);
		world.setBlock(i + 7, j + 13, k + 4, 0);
		world.setBlock(i + 7, j + 13, k + 5, 0);
		world.setBlock(i + 7, j + 13, k + 6, 0);
		world.setBlock(i + 7, j + 13, k + 7, 0);
		world.setBlock(i + 7, j + 13, k + 8, 0);
		world.setBlock(i + 7, j + 13, k + 9, 0);
		world.setBlock(i + 7, j + 13, k + 10, 0);
		world.setBlock(i + 7, j + 13, k + 11, Block.stoneBrick.blockID);
		world.setBlock(i + 7, j + 14, k + 0, 0);
		world.setBlock(i + 7, j + 14, k + 1, Block.stoneBrick.blockID);
		world.setBlock(i + 7, j + 14, k + 2, 0);
		world.setBlock(i + 7, j + 14, k + 3, 0);
		world.setBlock(i + 7, j + 14, k + 4, 0);
		world.setBlock(i + 7, j + 14, k + 5, 0);
		world.setBlock(i + 7, j + 14, k + 6, 0);
		world.setBlock(i + 7, j + 14, k + 7, 0);
		world.setBlock(i + 7, j + 14, k + 8, 0);
		world.setBlock(i + 7, j + 14, k + 9, 0);
		world.setBlock(i + 7, j + 14, k + 10, 0);
		world.setBlock(i + 7, j + 14, k + 11, Block.stoneBrick.blockID);
		world.setBlock(i + 7, j + 14, k + 12, 0);
		world.setBlock(i + 7, j + 15, k + 0, 0);
		world.setBlock(i + 7, j + 15, k + 1, 0);
		world.setBlock(i + 7, j + 15, k + 2, Block.stoneBrick.blockID);
		world.setBlock(i + 7, j + 15, k + 3, 0);
		world.setBlock(i + 7, j + 15, k + 5, 0);
		world.setBlock(i + 7, j + 15, k + 8, 0);
		world.setBlock(i + 7, j + 15, k + 9, 0);
		world.setBlock(i + 7, j + 15, k + 10, Block.stoneBrick.blockID);
		world.setBlock(i + 7, j + 15, k + 11, 0);
		world.setBlock(i + 7, j + 15, k + 12, 0);
		world.setBlock(i + 7, j + 16, k + 0, 0);
		world.setBlock(i + 7, j + 16, k + 1, 0);
		world.setBlock(i + 7, j + 16, k + 3, Block.stoneBrick.blockID);
		world.setBlock(i + 7, j + 16, k + 4, Block.web.blockID);
		world.setBlock(i + 7, j + 16, k + 5, 0);
		world.setBlock(i + 7, j + 16, k + 6, Block.web.blockID);
		world.setBlock(i + 7, j + 16, k + 7, 0);
		world.setBlock(i + 7, j + 16, k + 8, Block.web.blockID);
		world.setBlock(i + 7, j + 16, k + 9, Block.stoneBrick.blockID);
		world.setBlock(i + 7, j + 16, k + 10, 0);
		world.setBlock(i + 7, j + 16, k + 11, 0);
		world.setBlock(i + 7, j + 16, k + 12, 0);
		world.setBlock(i + 7, j + 17, k + 0, 0);
		world.setBlock(i + 7, j + 17, k + 1, 0);
		world.setBlock(i + 7, j + 17, k + 2, 0);
		world.setBlock(i + 7, j + 17, k + 4, Block.stoneBrick.blockID);
		world.setBlock(i + 7, j + 17, k + 5, 0);
		world.setBlock(i + 7, j + 17, k + 6, 0);
		world.setBlock(i + 7, j + 17, k + 7, Block.web.blockID);
		world.setBlock(i + 7, j + 17, k + 8, Block.stoneBrick.blockID);
		world.setBlock(i + 7, j + 17, k + 9, 0);
		world.setBlock(i + 7, j + 17, k + 10, 0);
		world.setBlock(i + 7, j + 17, k + 11, 0);
		world.setBlock(i + 7, j + 17, k + 12, 0);
		world.setBlock(i + 7, j + 18, k + 0, 0);
		world.setBlock(i + 7, j + 18, k + 1, 0);
		world.setBlock(i + 7, j + 18, k + 2, 0);
		world.setBlock(i + 7, j + 18, k + 3, 0);
		world.setBlock(i + 7, j + 18, k + 5, Block.stoneBrick.blockID);
		world.setBlock(i + 7, j + 18, k + 6, 0);
		world.setBlock(i + 7, j + 18, k + 7, Block.stoneBrick.blockID);
		world.setBlock(i + 7, j + 18, k + 8, 0);
		world.setBlock(i + 7, j + 18, k + 9, 0);
		world.setBlock(i + 7, j + 18, k + 10, 0);
		world.setBlock(i + 7, j + 18, k + 11, 0);
		world.setBlock(i + 7, j + 18, k + 12, 0);
		world.setBlock(i + 7, j + 19, k + 0, 0);
		world.setBlock(i + 7, j + 19, k + 1, 0);
		world.setBlock(i + 7, j + 19, k + 2, 0);
		world.setBlock(i + 7, j + 19, k + 3, 0);
		world.setBlock(i + 7, j + 19, k + 4, 0);
		world.setBlock(i + 7, j + 19, k + 5, 0);
		world.setBlock(i + 7, j + 19, k + 6, Block.stoneBrick.blockID);
		world.setBlock(i + 7, j + 19, k + 7, 0);
		world.setBlock(i + 7, j + 19, k + 8, 0);
		world.setBlock(i + 7, j + 19, k + 9, 0);
		world.setBlock(i + 7, j + 19, k + 10, 0);
		world.setBlock(i + 7, j + 19, k + 11, 0);
		world.setBlock(i + 7, j + 19, k + 12, 0);
		world.setBlock(i + 8, j + 0, k + 0, 0);
		world.setBlock(i + 8, j + 0, k + 1, Block.stone.blockID);
		world.setBlock(i + 8, j + 0, k + 2, Block.cloth.blockID);
		world.setBlock(i + 8, j + 0, k + 3, Block.cloth.blockID);
		world.setBlock(i + 8, j + 0, k + 4, Block.cloth.blockID);
		world.setBlockMetadataWithNotify(i + 8, j + 0, k + 5, Block.cloth.blockID, 8);
		world.setBlockMetadataWithNotify(i + 8, j + 0, k + 6, Block.cloth.blockID, 14);
		world.setBlock(i + 8, j + 0, k + 7, Block.cloth.blockID);
		world.setBlock(i + 8, j + 0, k + 8, Block.cloth.blockID);
		world.setBlock(i + 8, j + 0, k + 9, Block.cloth.blockID);
		world.setBlock(i + 8, j + 0, k + 10, Block.cloth.blockID);
		world.setBlock(i + 8, j + 0, k + 11, Block.stone.blockID);
		world.setBlock(i + 8, j + 0, k + 12, 0);
		world.setBlock(i + 8, j + 1, k + 0, 0);
		world.setBlock(i + 8, j + 1, k + 1, Block.stone.blockID);
		world.setBlock(i + 8, j + 1, k + 2, Block.stoneBrick.blockID);
		world.setBlock(i + 8, j + 1, k + 3, Block.stoneBrick.blockID);
		world.setBlock(i + 8, j + 1, k + 4, 0);
		world.setBlock(i + 8, j + 1, k + 5, 0);
		world.setBlock(i + 8, j + 1, k + 6, 0);
		world.setBlock(i + 8, j + 1, k + 7, Block.web.blockID);
		world.setBlock(i + 8, j + 1, k + 8, 0);
		world.setBlock(i + 8, j + 1, k + 9, Block.stoneBrick.blockID);
		world.setBlock(i + 8, j + 1, k + 10, Block.stoneBrick.blockID);
		world.setBlock(i + 8, j + 1, k + 11, Block.silverfish.blockID);
		world.setBlock(i + 8, j + 1, k + 12, 0);
		world.setBlock(i + 8, j + 2, k + 0, 0);
		world.setBlock(i + 8, j + 2, k + 1, Block.stone.blockID);
		world.setBlock(i + 8, j + 2, k + 2, Block.web.blockID);
		world.setBlock(i + 8, j + 2, k + 3, 0);
		world.setBlock(i + 8, j + 2, k + 4, 0);
		world.setBlock(i + 8, j + 2, k + 5, 0);
		world.setBlock(i + 8, j + 2, k + 6, 0);
		world.setBlock(i + 8, j + 2, k + 7, 0);
		world.setBlock(i + 8, j + 2, k + 8, 0);
		world.setBlock(i + 8, j + 2, k + 9, Block.web.blockID);
		world.setBlock(i + 8, j + 2, k + 10, 0);
		world.setBlock(i + 8, j + 2, k + 11, Block.stone.blockID);
		world.setBlock(i + 8, j + 2, k + 12, 0);
		world.setBlock(i + 8, j + 3, k + 1, Block.stone.blockID);
		world.setBlock(i + 8, j + 3, k + 2, 0);
		world.setBlock(i + 8, j + 3, k + 3, 0);
		world.setBlock(i + 8, j + 3, k + 4, 0);
		world.setBlock(i + 8, j + 3, k + 5, 0);
		world.setBlock(i + 8, j + 3, k + 6, 0);
		world.setBlock(i + 8, j + 3, k + 7, 0);
		world.setBlock(i + 8, j + 3, k + 8, 0);
		world.setBlock(i + 8, j + 3, k + 9, 0);
		world.setBlock(i + 8, j + 3, k + 10, 0);
		world.setBlock(i + 8, j + 3, k + 11, Block.stone.blockID);
		world.setBlock(i + 8, j + 3, k + 12, 0);
		world.setBlock(i + 8, j + 4, k + 0, 0);
		world.setBlock(i + 8, j + 4, k + 1, Block.stone.blockID);
		world.setBlock(i + 8, j + 4, k + 2, 0);
		world.setBlock(i + 8, j + 4, k + 3, 0);
		world.setBlock(i + 8, j + 4, k + 4, 0);
		world.setBlock(i + 8, j + 4, k + 5, 0);
		world.setBlock(i + 8, j + 4, k + 6, 0);
		world.setBlock(i + 8, j + 4, k + 7, 0);
		world.setBlock(i + 8, j + 4, k + 8, 0);
		world.setBlock(i + 8, j + 4, k + 9, 0);
		world.setBlock(i + 8, j + 4, k + 10, 0);
		world.setBlock(i + 8, j + 4, k + 11, Block.stone.blockID);
		world.setBlock(i + 8, j + 4, k + 12, 0);
		world.setBlock(i + 8, j + 5, k + 1, Block.stoneBrick.blockID);
		world.setBlock(i + 8, j + 5, k + 2, 0);
		world.setBlock(i + 8, j + 5, k + 3, 0);
		world.setBlock(i + 8, j + 5, k + 4, 0);
		world.setBlock(i + 8, j + 5, k + 5, 0);
		world.setBlock(i + 8, j + 5, k + 6, 0);
		world.setBlock(i + 8, j + 5, k + 7, 0);
		world.setBlock(i + 8, j + 5, k + 8, 0);
		world.setBlock(i + 8, j + 5, k + 9, 0);
		world.setBlock(i + 8, j + 5, k + 10, 0);
		world.setBlock(i + 8, j + 5, k + 11, Block.stoneBrick.blockID);
		world.setBlock(i + 8, j + 5, k + 12, 0);
		world.setBlock(i + 8, j + 6, k + 1, Block.stone.blockID);
		world.setBlock(i + 8, j + 6, k + 2, 0);
		world.setBlock(i + 8, j + 6, k + 3, 0);
		world.setBlock(i + 8, j + 6, k + 4, 0);
		world.setBlock(i + 8, j + 6, k + 5, 0);
		world.setBlock(i + 8, j + 6, k + 6, 0);
		world.setBlock(i + 8, j + 6, k + 7, 0);
		world.setBlock(i + 8, j + 6, k + 8, 0);
		world.setBlock(i + 8, j + 6, k + 9, 0);
